Workbook

Sheet 首页索引
A1: 系统名称 | B1: 感谢豆油们提供的部分资料支持 | M1: 中秋祝福
A2: 日常综合 | B2: 侠士综合 | C2: 门派心法 | D2: 武器专精 | E2: 全民乱斗 | F2: 斗技场景 | G2: 助阵天书 | H2: 助阵算术 | I2: 天象洗髓 | J2: 元婴仙化 | K2: 角色经验 | L2: x | M2: x
B3: 佣兵综合 | C3: 门派武技 | D3: 武器封印 | E3: 飞升化境 | F3: 上古神魔 | G3: 助阵洛书 | H3: 附魔上页 | I3: 奇树灵鉴 | J3: 多种系统 | K3: 发展历程 | L3: x | M3: x
B4: 神将综合 | C4: 神装神技 | D4: 武器铭刻 | E4: 仙武修真 | F4: 匠心功艺 | G4: 助阵八卦 | H4: 附魔下页 | I4: 龙凰之境 | J4: 徽章成就 | K4: 补充拓展 | L4: x | M4: x
B5: 武器综合 | C5: 奥义奥技 | D5: 槽位符石 | E5: 名册宝鉴 | F5: 灵枢精魄 | G5: 助阵内经 | H5: 器魂绘卷 | I5: 元武职业 | J5: 经脉内力 | K5: x | L5: x | M5: x
A6: 蓝字处均可点击快速跳转详表。详表根据表内红字祝福类型自动读取相应数值计算，详表内黄色填充为待补充或待确认内容。
A7: 循环活动 | B7: 2026/6/18 | C7: 2026/6/25 | D7: 2026/7/2 | E7: 2026/7/9 | F7: 2026/7/16 | G7: 2026/7/23 | H7: 2026/7/30 | I7: 2026/8/6 | J7: 2026/8/13 | K7: 2026/8/20 | L7: 2026/8/27 | M7: 2026/9/3
A8: 每2周 | B8: 魂珠三折 | C8: 五行祝福 | D8: 魂珠三折 | E8: 五行祝福 | F8: 魂珠三折 | G8: 五行祝福 | H8: 魂珠三折 | I8: 五行祝福 | J8: 魂珠三折 | K8: 五行祝福 | L8: 魂珠三折 | M8: 五行祝福
B9: x | C9: 传功祝福 | D9: x | E9: 传功祝福 | F9: x | G9: 传功祝福 | H9: x | I9: 传功祝福 | J9: x | K9: 传功祝福 | L9: x | M9: 传功祝福
A10: 每3周 | B10: 铭刻祝福 | C10: 神装祝福 | D10: 门派祝福 | E10: 铭刻祝福 | F10: 神装祝福 | G10: 门派祝福 | H10: 铭刻祝福 | I10: 神装祝福 | J10: 门派祝福 | K10: 铭刻祝福 | L10: 神装祝福 | M10: 门派祝福
B11: 助阵祝福 | C11: 斗技祝福 | D11: 奥义祝福 | E11: 助阵祝福 | F11: 斗技祝福 | G11: 奥义祝福 | H11: 助阵祝福 | I11: 斗技祝福 | J11: 奥义祝福 | K11: 助阵祝福 | L11: 斗技祝福 | M11: 奥义祝福
B12: 兵法祝福 | C12: 槽位祝福 | D12: 专精祝福 | E12: 兵法祝福 | F12: 槽位祝福 | G12: 专精祝福 | H12: 兵法祝福 | I12: 槽位祝福 | J12: 专精祝福 | K12: 兵法祝福 | L12: 槽位祝福 | M12: 专精祝福
B13: 强化祝福 | C13: 仙化祝福 | D13: 神魔祝福 | E13: 强化祝福 | F13: 仙化祝福 | G13: 神魔祝福 | H13: 强化祝福 | I13: 仙化祝福 | J13: 神魔祝福 | K13: 强化祝福 | L13: 仙化祝福 | M13: 神魔祝福
B14: 福缘仙树 | C14: 徽章祝福 | D14: 神魔转盘 | E14: 福缘仙树 | F14: 徽章祝福 | G14: 神魔转盘 | H14: 福缘仙树 | I14: 徽章祝福 | J14: 神魔转盘 | K14: 福缘仙树 | L14: 徽章祝福 | M14: 神魔转盘
B15: 深渊秘宝 | C15: 佣兵夺宝 | D15: 黄金招财 | E15: 深渊秘宝 | F15: 佣兵夺宝 | G15: 黄金招财 | H15: 深渊秘宝 | I15: 佣兵夺宝 | J15: 黄金招财 | K15: 深渊秘宝 | L15: 佣兵夺宝 | M15: 黄金招财
B16: 达人六折 | C16: 佣兵宝箱 | D16: 星盘六折 | E16: 达人六折 | F16: 佣兵宝箱 | G16: 星盘六折 | H16: 达人六折 | I16: 佣兵宝箱 | J16: 星盘六折 | K16: 达人六折 | L16: 佣兵宝箱 | M16: 星盘六折
B17: 侠士商城 | C17: 花果山 | D17: 王子福袋 | E17: 侠士商城 | F17: 花果山 | G17: 王子福袋 | H17: 侠士商城 | I17: 花果山 | J17: 王子福袋 | K17: 侠士商城 | L17: 花果山 | M17: 王子福袋
B18: 幸运夺宝 | C18: x | D18: 娃娃机 | E18: 幸运夺宝 | F18: x | G18: 娃娃机 | H18: 幸运夺宝 | I18: x | J18: 娃娃机 | K18: 幸运夺宝 | L18: x | M18: 娃娃机
A19: 仙武推荐 | B19: 力量张三丰 | C19: 速度无崖子 | D19: 敏捷帝释天 | E19: 力量张三丰 | F19: 速度无崖子 | G19: 敏捷帝释天 | H19: 力量张三丰 | I19: 速度无崖子 | J19: 敏捷帝释天 | K19: 力量张三丰 | L19: 速度无崖子 | M19: 敏捷帝释天
A20: 每4周 | B20: 佣兵还童 | C20: 洗练画册 | D20: 佣兵特惠 | E20: 佣兵悟性 | F20: 佣兵还童 | G20: 洗练画册 | H20: 佣兵特惠 | I20: 佣兵悟性 | J20: 佣兵还童 | K20: 洗练画册 | L20: 佣兵特惠 | M20: 佣兵悟性
B21: 预定领取 | C21: 幸运折扣 | D21: 超值礼包 | E21: 佣兵预定 | F21: 预定领取 | G21: 幸运折扣 | H21: 超值礼包 | I21: 佣兵预定 | J21: 预定领取 | K21: 幸运折扣 | L21: 超值礼包 | M21: 佣兵预定
B22: 九宫宝库 | C22: 九宫宝库 | D22: 优惠商店 | E22: 优惠商店 | F22: 九宫宝库 | G22: 九宫宝库 | H22: 优惠商店 | I22: 优惠商店 | J22: 九宫宝库 | K22: 九宫宝库 | L22: 优惠商店 | M22: 优惠商店
B23: 符石宝箱 | C23: x | D23: 神将夺宝 | E23: 符石宝箱 | F23: 符石宝箱 | G23: x | H23: 神将夺宝 | I23: 符石宝箱 | J23: 符石宝箱 | K23: x | L23: 神将夺宝 | M23: 符石宝箱
B24: 邪神特卖9 | C24: x | D24: 邪神特卖8 | E24: x | F24: 邪神特卖9 | G24: x | H24: 邪神特卖8 | I24: x | J24: 邪神特卖9 | K24: x | L24: 邪神特卖8 | M24: x
A25: 每6周 | B25: 菜菜厨房 | C25: 豪华套餐 | D25: 登录有礼 | E25: 登录商店 | F25: 乐斗能量 | G25: 每日首兑 | H25: 菜菜厨房 | I25: 豪华套餐 | J25: 登录有礼 | K25: 登录商店 | L25: 乐斗能量 | M25: 每日首兑
B26: 幸运金蛋 | C26: 幸运转盘 | D26: 猜单双 | E26: 活跃礼包 | F26: 周周礼包 | G26: 好礼提升 | H26: 幸运金蛋 | I26: 幸运转盘 | J26: 猜单双 | K26: 活跃礼包 | L26: 周周礼包 | M26: 好礼提升
A27: 该表收纳于官方活动常规排期，会跟随官方改动而更新数据。
A28: 特殊节点 | B28: 除上表所列活动以外的其它活动（上表活动在三大节庆期间可能会临时调整周期或内容导致与表内不符）
A29: 春节 | B29: 大侠回归 | C29: 超级返利 | D29: 刮刮卡 | E29: 吉利兑 | F29: 仙武祝福 | G29: 乱斗祝福 | H29: 星盘五折 | I29: 内力三折 | J29: 问道十连 | K29: 铁匠六折 | L29: 新春boss | M29: 年兽作战
B30: 生肖古玩 | C30: 生肖年卡 | D30: 燃放烟花 | E30: 春联大赛 | F30: 新春拜年 | G30: 春节累登 | H30: 斗友召回 | I30: x | J30: x | K30: x | L30: x | M30: x
A31: 周年 | B31: 大侠回归 | C31: 超级返利 | D31: 刮刮卡 | E31: 吉利兑 | F31: 仙武祝福 | G31: 乱斗祝福 | H31: 星盘五折 | I31: 内力三折 | J31: 问道十连 | K31: 铁匠六折 | L31: 魂珠特惠 | M31: 深渊特惠
B32: 长安盛会 | C32: 周年福卡 | D32: 周年巡礼 | E32: 预热礼包 | F32: 预约抽奖 | G32: 生日祝福 | H32: 激运牌 | I32: x | J32: x | K32: x | L32: x | M32: x
A33: 中秋/国庆 | B33: 大侠回归 | C33: 超级返利 | D33: 刮刮卡 | E33: 吉利兑 | F33: 仙武祝福 | G33: 乱斗祝福 | H33: 中秋月饼 | I33: 中秋礼盒 | J33: 问道十连 | K33: x | L33: x | M33: x
A34: 其它节庆 | B34: 多倍福利 | C34: 限定武器 | D34: 限定徽章 | E34: 元宵活动 | F34: 缅怀金庸 | G34: 五一礼包 | H34: 预订礼包 | I34: 端午粽子 | J34: 同心结 | K34: 太白诗会 | L34: 点亮南瓜 | M34: 节日彩灯
B35: 五大节庆 | C35: 五大节庆 | D35: 四大节庆 | E35: 元宵节 | F35: 清明节 | G35: 劳动节 | H35: 劳动节 | I35: 端午节 | J35: 七夕节 | K35: 重阳节 | L35: 万圣节 | M35: 圣诞节
A36: 其它周期 | B36: 开学礼包 | C36: 客栈对酒 | D36: 常规返利 | E36: 消费抽奖 | F36: 斗豆商城 | G36: 优惠秘籍 | H36: 节气锦囊 | I36: 年兽福蛋 | J36: 跨年签到 | K36: 年度回忆 | L36: 迎新礼包 | M36: 大笨钟
B37: 2/6/9月 | C37: 每6周 | D37: 每5周 | E37: 伴随返利 | F37: 伴随返利 | G37: 伴随返利 | H37: 逢节气 | I37: 每年底 | J37: 每年底 | K37: 每年底 | L37: 每年底 | M37: 每年底
A38: 未定周期 最近日期 | B38: 星宫宝库 | C38: 女神药妆 | D38: 乐斗游记 | E38: 斗境探秘 | F38: 小丑魔盒 | G38: 限时副本 | H38: 微信兑换 | I38: 徽章战令 | J38: 江湖秘宝 | K38: 全服抢购 | L38: 至尊宝典 | M38: 乐斗驿站
B39: 2026/4/2 | C39: 2026/3/19 | D39: 2026/3/26 | E39: 2026/2/19 | F39: 2026/3/12 | G39: 2026/4/2 | H39: 2026/2/5 | I39: 2026/4/9 | J39: 2026/9/18 | K39: 2026/1/22 | L39: 2026/3/5 | M39: 2026/3/26
B40: 长梦刷新 | C40: 深渊刷新 | D40: 飞升结算 | E40: 招募更新 | F40: 深渊福利 | G40: 佣兵新品 | H40: x | I40: x | J40: x | K40: x | L40: x | M40: x
...

Sheet 日常综合
A1: 日常综合 | B1: 锦囊宝箱 | C1: 帮派商会 | D1: 赛事奖励 | E1: 属性加成 | F1: 帮派任务 | G1: 门派任务 | H1: 日常任务 | I1: 喝汤变化 | J1: 历练首领 | K1: 镖行天下
A2: 幸运金蛋 | B2: 幸运转盘 | C2: 神魔转盘 | D2: 消费抽奖 | E2: 活跃礼包 | F2: 大笨钟 | G2: 花果山 | H2: 佣兵宝箱 | I2: 神将夺宝 | J2: 佣兵夺宝 | K2: 深渊秘宝 | L2: 达人六折
A3: 黄金招财 | B3: 福缘仙树 | C3: 王子福袋 | D3: 年兽福蛋 | E3: 江湖秘宝 | F3: 全服抢购 | G3: 多倍福利 | H3: 吉利兑 | I3: 女神药妆 | J3: 超值礼包 | K3: 徽章战令 | L3: 生肖年卡
A4: 热卖商城 | B4: 侠士商城 | C4: 佣兵特惠 | D4: 佣兵预定 | E4: 佣兵新品 | F4: 优惠秘籍 | G4: 邪神特卖 | H4: 乐斗驿站 | I4: 小丑魔盒 | J4: 开学礼包 | K4: 幸运折扣 | L4: 优惠商店
A5: 斗豆商城 | B5: 符石宝箱 | C5: 星宫宝库 | D5: 幸运夺宝 | E5: 乐斗游记 | F5: 斗境探秘 | G5: 大侠回归 | H5: 至尊宝典 | I5: 客栈对酒 | J5: 九宫宝库 | K5: 娃娃机 | L5: 刮刮卡
A6: 鹅币返利 | B6: 年兽作战 | C6: 返利排行 | D6: 微信兑换 | E6: x | F6: x | G6: x | H6: x | I6: x | J6: x | K6: x | L6: x
A8: 名称 | B8: 获取途径 | C8: 奖励池
A9: 斗技小宝箱 | B9: 黄金联赛 | C9: 随机：武魂符、战魂符、斗魂符，固定：数量合计1个
A10: 斗技中宝箱 | B10: 黄金联赛 | C10: 随机：武魂符、战魂符、斗魂符，固定：数量合计3个
A11: 斗技大宝箱 | B11: 黄金联赛 | C11: 随机：武魂符、战魂符、斗魂符，固定：数量合计5个
A12: 佣兵小宝箱 | B12: 任务派遣 | C12: 随机：令狐冲/丁春秋/丘处机/小龙女/韦小宝/扫地僧/鹤笔翁/韦一笑/赵敏碎片1
A13: 佣兵中宝箱 | B13: 任务派遣 | C13: 随机：顶级令狐冲/顶级扫地僧/顶级韦一笑/独孤求败/达摩祖师/黑山老妖碎片1
A14: 佣兵大宝箱 | B14: 任务派遣 | C14: 随机：齐天大圣/诸葛孔明/乐斗忍者/鹤仙人/豆油队长/东方不败/钢铁侠/锦鲤仙人碎片1
A15: 神将宝箱 | B15: 任务派遣 | C15: 随机：菜菜大侠/剑君大侠/帅帅大侠/熊猫潘达/金毛狮王碎片1
A16: 铭刻宝箱 | B16: 武林盟主 | C16: 随机：除奇异的画笔外任意5种，固定：数量每种5个
A17: 神装宝箱 | B17: 武林盟主 | C17: 固定：神兵原石1+软猥金丝1+凤凰羽毛1+潜能果实1+上古玉髓1+奔流气息1+神秘精华1
A18: 铜质宝箱 | B18: 每日宝箱 | C18: 固定：徽章符石3，随机：传功符5、无字天书3、巅峰之战二等勋章1(金银铜每天最多各打开10次)
A19: 银质宝箱 | B19: 每日宝箱 | C19: 固定：孙子兵法4+武穆遗书4，随机：2级幸运石2、巅峰之战一等勋章1、2级剑君/菜菜魂珠1
... A83: 每日增益 | B83: 乐斗黄历 | C83: 斗神塔掉落及每日奖励双倍、画卷材料双倍、副本经验双倍(包含画卷、十二宫)、乐斗经验双倍、历练阅历双倍、暂无
A85: 商会交易会所 | C85: 银币 | D85: 商会交易会所 | F85: 银币 | G85: 商会交易会所 | I85: 银币 | J85: 商会交易会所 | L85: 银币
A86: 小体力*10 | C86: 20 | D86: 许愿卡*1 | F86: 400 | G86: 悟性丹*10 | I86: 25 | J86: 神兵原石*5 | L86: 200
A87: 大体力/活力药*5 | C87: 25 | D87: 孟婆汤*1 | F87: 150 | G87: 悟性丹*20 | I87: 100 | J87: 软猥金丝*5 | L87: 200
A88: 真体力*5 | C88: 50 | D88: 葵花宝典*1 | F88: 50 | G88: 还童卷轴*5 | I88: 100 | J88: 凤凰羽毛*5 | L88: 200
A89: 贡献药水*5 | C89: 20 | D89: 大经验药水*1 | F89: 30 | G89: 还童天书*2 | I89: 100 | J89: 潜能果实*5 | L89: 200
A90: 神来拳套*5 | C90: 45 | D90: 贡献药水百*5 | F90: 250 | G90: 百炼钢*5 | I90: 100 | J90: 上古玉髓*5 | L90: 200
A91: 经验药水*5 | C91: 50 | D91: 神来拳套百*1 | F91: 100 | G91: 黄金卷轴*5 | I91: 100 | J91: 奔流气息*5 | L91: 200
A92: 挑战书*5 | C92: 25 | D92: 经验药水七天*5 | F92: 250 | G92: 孙子兵法*5 | I92: 100 | J92: 投掷武器符文石*5 | L92: 200
A93: 还魂丹*20 | C93: 10 | D93: 被动经验药水七天*1 | F93: 60 | G93: 无字天书*10 | I93: 100 | J93: 小型武器符文石*5 | L93: 200
A94: 寻斗符*20 | C94: 20 | D94: 巅峰之战二等勋章*2 | F94: 100 | G94: 经验木简*10 | I94: 100 | J94: 中型武器符文石*5 | L94: 200
A95: 追魂锁链*5 | C95: 25 | D95: 巅峰之战一等勋章*1 | F95: 200 | G95: 阅历羊皮卷*10 | I95: 100 | J95: 大型武器符文石*5 | L95: 200
A96: 无字天书*10 | C96: 100 | D96: 河图洛书*10 | F96: 100 | G96: 易经八卦*10 | I96: 100 | J96: 孙子兵法*5 | L96: 100
... A98: 无字天书*40 | C98: 200 | D98: 河图洛书*40 | F98: 200 | G98: 易经八卦*40 | I98: 200 | J98: 孙子兵法*20 | L98: 200
A99: 武穆遗书*5 | C99: 100 | D99: 武穆遗书*10 | F99: 200 | G99: 武穆遗书*20 | I99: 200
A100: 商会兑换商店 | C100: 银币 | D100: 商会兑换商店 | F100: 银币 | G100: 商会兑换商店 | I100: 银币 | J100: 商会兑换商店 | L100: 银币
A101: 1级日曜石*1 | C101: 228 | D101: 1级狂暴石*1 | F101: 300 | G101: 闪耀·暴风Ⅴ碎片*1 | I101: 9000 | J101: 破坏·暴风Ⅴ碎片*1 | L101: 9000
A102: 1级玛瑙石*1 | C102: 198 | D102: 1级神愈石*1 | F102: 300 | G102: 闪耀·狂风Ⅴ碎片*1 | I102: 9000 | J102: 破坏·狂风Ⅴ碎片*1 | L102: 9000
A103: 1级迅捷石*1 | C103: 198 | D103: 1级狂暴石*2 | F103: 600 | G103: 闪耀·霸风Ⅴ碎片*1 | I103: 9000 | J103: 破坏·霸风Ⅴ碎片*1 | L103: 9000
A104: 1级月光石*1 | C104: 158 | D104: 1级神愈石*2 | F104: 600 | G104: 闪耀·流风Ⅴ碎片*1 | I104: 9000 | J104: 破坏·流风Ⅴ碎片*1 | L104: 9000
A105: 1级翡翠石*1 | C105: 158 | D105: 1级狂暴石*5 | F105: 1500 | G105: 闪耀·幽月Ⅴ碎片*1 | I105: 9000 | J105: 破坏·幽月Ⅴ碎片*1 | L105: 9000
A106: 1级紫黑玉*1 | C106: 158 | D106: 1级神愈石*5 | F106: 1500 | G106: 闪耀·清月Ⅴ碎片*1 | I106: 9000 | J106: 破坏·清月Ⅴ碎片*1 | L106: 9000
...

Sheet 侠士综合
A1: 侠士综合 | B1: 名词解释 | C1: 技能等级 | D1: 论剑组合 | E1: 领奖奇遇 | F1: 升级属性 | G1: 食珍录 | H1: 古玩赏 | I1: 见闻志 | K1: 阴属性 | L1: 阳属性
A2: 金属性 | B2: 柒承 | C2: 段智兴 | D2: 杨过 | E2: 金轮法王 | F2: 王处一 | G2: 胡斐 | H2: x | I2: x | J2: x | K2: x | L2: 鹅晓峰
A3: 木属性 | B3: 九品芝麻官 | C3: 黄药师 | D3: 林朝英 | E3: 周伯通 | F3: 周芷若 | G3: 行者鹅 | H3: 木岛主 | I3: 鹅乔峰 | J3: x | K3: x | L3: x
A4: 土属性 | B4: 李师师 | C4: 圣诞老鹅 | D4: 杜十三 | E4: 李莫愁 | F4: 梅超风 | G4: 石破天 | H4: 发财鹅 | I4: x | J4: x | K4: x | L4: x
A5: 水属性 | B5: 断亦 | C5: 王重阳 | D5: 欧阳锋 | E5: 小龙女 | F5: 郭襄 | G5: 龙岛主 | H5: 笑红尘 | I5: 越女鹅 | J5: x | K5: x | L5: x
A6: 火属性 | B6: 燕青 | C6: 洪七公 | D6: 李光弼 | E6: 郭靖 | F6: 张无忌 | G6: 张三丰 | H6: 斗酒僧 | I6: 福马鹅 | J6: x | K6: x | L6: x
A8: 名称 | B8: 相关概念及规则说明
A9: 五行克制 | B9: 攻击被克制属性的侠士时，增加20%伤害。克制顺序为：金克木，木克土，土克水，水克火，火克金。
A10: 阴阳克制 | B10: 阳克阴，阳克金火，阳弱克土；阴克阳，阴克木水，阳弱克土。弱克只增加10%伤害.
A11: 初始属性 | B11: 1级侠士初始属性或满级侠士生命若与表内侠士资料不一致，原因是武技栏已有属性技能提供了加成。
A12: 侠士职业 | B12: 盾/拳/刀/刺/剑客分别为生命/力量/敏捷/速度/均衡型侠士，各自偏向更高的生命/力量/敏捷/速度成长或平衡成长。
A13: 成长系数 | B13: 不同品级侠士有不同成长系数，同一侠士根据职业不同，不同属性的成长系数也不完全相同。本数据表内仅记录生命成长系数。
A14: 属性成长 | B14: 侠士在初始属性的基础上，每次升级随机力/速/敏中其二增加1*成长系数（可为相同属性），生命增加5*成长系数。
A15: 重出江湖 | B15: 消耗重出江湖令，侠士初始属性不变，已有武技种类不变，已解锁武技栏不变。
A16: 武技顺序 | B16: 当侠士武器技能中存在两个或两个以上技能时，排在可多次触发的技能之后的技能将无法触发。
A17: 武技重置 | B17: 消耗侠士修身录，建议解锁全5个武技栏后再参考推荐武技重置。
A18: 客栈奇遇 | B18: 物品交换，特价道具、侠士捣乱。出现时间每日早6点以及晚6点，最多保留2个奇遇。
A19: 客栈领奖 | B19: 包括住客NPC和食客NPC，不同NPC有不同的奖励配置权重。
... A22: 菜谱熟练 | B22: 菜谱有隐藏的七维度属性，熟练度升级会影响七维属性，七维属性会影响出现的食客NPC。
A24: 技能等级 | B24: LV1 | C24: LV2 | D24: LV3 | E24: LV4 | F24: LV5 | H24: 赛季加成 | I24: 单同五行 | J24: 双同五行 | K24: 三同五行
A25: 常规碎片 | B25: 20 | C25: 50 | D25: 120 | E25: 160 | F25: 500 | H25: 固定五行 | I25: 生命8% | J25: 生命10% | K25: 生命12%
A26: 冠侠碎片 | B26: 20 | C26: 50 | D26: 120 | E26: 160 | F26: 500 | I26: 力量8% | J26: 力量10% | K26: 力量12%
A27: 豪侠碎片 | B27: 50 | C27: 100 | D27: 150 | E27: 200 | F27: 600 | H27: 碧水寒潭 水属性 | I27: 暴击6% | J27: 暴击12% | K27: 暴击18%
A28: 福侠碎片 | B28: 50 | C28: 100 | D28: 150 | E28: 200 | F28: 600 | I28: 速度3% | J28: 速度6% | K28: 速度9%
A29: 隐侠碎片 | B29: 3隐侠贴 | C29: 50 | H29: 苍林竹海 木属性 | I29: 命中6% | J29: 命中12% | K29: 命中18%
A30: 秘卷技能 | B30: 1秘卷 | C30: 50 | D30: 100 | E30: 150 | F30: 200 | I30: 速度3% | J30: 速度6% | K30: 速度9%
A31: 论剑耐久 | B31: 10 | C31: 15 | D31: 20 | E31: 25 | F31: 30 | H31: 烈焰熔谷 火属性 | I31: 暴击6% | J31: 暴击12% | K31: 暴击18%
A32: 每日恢复 | B32: 5 | C32: 8 | D32: 11 | E32: 14 | F32: 18 | I32: 武伤6% | J32: 武伤12% | K32: 武伤18%
H33: 金属性
C34: 单阴阳 | D34: 生命10% | E34: 生命12% | F34: x
D35: 力量10% | E35: 力量12% | F35: x | H35: 土属性
A38: 食珍录 | B38: 激活菜谱 | C38: 满级菜谱 | E38: 奇遇物品交换 | G38: 消耗材料 | I38: 奇遇物品交换 | K38: 消耗材料
A39: 白粥 | B39: x | C39: =(500+500+1000+2000)/50 | E39: Ⅴ级万能碎片*1 | G39: 斗灵石-空*66 | I39: 百炼钢*2 | K39: 黄金卷轴*3
A40: 蛋炒饭 | B40: x | C40: =(500+500+1000+2000)/50 | E40: 斗灵石-空*5 | G40: 门派强化书*2 | I40: 百炼钢*1 | K40: 悟性丹* 6
A41: 叫花鸡 | B41: x | C41: =(500+500+1000+2000)/50 | E41: 斗灵石-空*5 | G41: 黄金卷轴*2 | I41: 百炼钢*1 | K41: 寻斗符*15
A42: 咸菜拼盘 | B42: x | C42: =(500+500+1000+2000)/50 | E42: 斗神符*1 | G42: 黄金卷轴*3 | I42: 百炼钢*1 | K42: 还魂丹*30
A43: 粗茶 | B43: x | C43: =(500+500+1000+2000)/50 | E43: 玄铁令*1 | G43: 挑战书* 2 | I43: 时之沙*2 | K43: 还魂丹*30
A44: 浊酒 | B44: 20 | C44: =(800+800+1600+3200)/50 | E44: 淬火结晶*1 | G44: 斗神符*1 | I44: 移魂符*1 | K44: 斗神符*1
A45: 麻婆豆腐 | B45: 40 | C45: =(1000+1000+2000+4000)/50 | E45: 易经八卦*1 | G45: 无字天书*1 | I45: 真黄金卷轴*1 | K45: 斗神符*1
A46: 陈醋花生米 | B46: 60 | C46: =(1200+1200+2400+4800)/50 | E46: 打尖住店领奖 | G46: 打尖住店领奖 | I46: 奇遇特价道具 | K46: 斗币/斗豆/鹅币
...

Sheet 佣兵综合
A1: 佣兵综合 | B1: 状态类 | F1: 战斗类 | J1: 防御类
A2: 名词解释 | B2: 鹤仙人 | C2: 豆油队长 | D2: 东方不败 | E2: 锦鲤仙人 | F2: 令狐冲 | G2: 顶级令狐冲 | H2: 独孤求败 | I2: 丁春秋 | J2: 丘处机 | K2: 扫地僧 | L2: 顶级扫地僧 | M2: 达摩祖师
A3: 天赋汇总 | B3: 钢铁侠 | C3: 鹿仙人 | D3: 我爱鹅 | E3: 赵云 | F3: 韦一笑 | G3: 顶级韦一笑 | H3: 黑山老妖 | I3: 鹤笔翁 | J3: 赵敏 | K3: 诸葛孔明 | L3: 乐斗忍者 | M3: 黄盖
A4: 天赋消耗 | B4: 无崖子 | C4: 鹅右介 | D4: 年兽大人 | E4: 贾诩 | F4: 小龙女 | G4: 韦小宝 | H4: 齐天大圣 | I4: 经阁扫地僧 | J4: 草薙鹅 | K4: 鹅灵儿 | L4: 御天战鹅 | M4: 郭嘉
A5: 佣兵派遣 | B5: 精灵鹅 | C5: x | D5: x | E5: x | F5: 周瑜 | G5: 鹅斯拉 | H5: 八神鹅 | I5: 鹅逍遥 | J5: 山丘鹅 | K5: x | L5: x | M5: x
A6: x | B6: x | C6: x | D6: x | E6: x | F6: 鹅离雨 | G6: 剑圣鹅 | H6: x | I6: x | J6: x | K6: x | L6: x | M6: x
A7: 活动详情：所有佣兵还童概率/提升悟性成功率大提升（6大稀有佣兵、齐天大圣、诸葛孔明除外），还童卷轴/还童天书/悟性丹无折扣。
A8: 名称 | B8: 相关概念及注意事项
A9: 佣兵还童 | B9: 还童至极品时会显示“您的佣兵资质已达顶级”，此时无法继续还童，一旦升级佣兵后，便又可继续还童，所以切勿胡乱点击。
A10: 佣兵等级 | B10: 务必先把悟性升至10以后再升级佣兵。佣兵升满20级总计需123500经验，普通突飞总计需61800阅历，勿花斗豆双倍突飞。
A11: 佣兵战力 | B11: 满悟性满等级的卓越佣兵战力均为95，且系统内显示的上阵佣兵/非上阵佣兵/佣兵天赋战力需分别乘以0.05/0.02/0.1系数后才加到人物战力。
A12: 佣兵顺序 | B12: 状态/战斗/防御类在实战中会按照顺序先后入场触发技能。状态佣兵均在开局触发，后两者除本身技能触发条件外还有额外的触发血线要求。
A13: 佣兵黄盖 | B13: 黄盖因为佣兵出场顺序的限制，救不了开局被秒杀。黄盖出手时会使对手当前回合的行动强制结束，和触发装死类技能的隐藏效果一样。
A14: 佣兵八神 | B14: 八神和东方均为拿不出武器而非禁止武器，表现为当其手持武器时，下回合若判定其继续使用当前武器则可用，若判定使用新武器，才会转为空手。
A15: 佣兵搭配 | B15: 后手我爱鹅弹不了东方不败。鹤仙人防不了八神，其速度加成也影响不了先手判定。先手队长+八神时，八神开局触发后队长技能被浪费。
A16: 佣兵年兽 | B16: 目前时效佣兵仅有年兽大人一种，每次使用时效道具激活后直接为满级极品，无需进行还童、升悟性、升等级等操作。
A18: 天赋汇总 | B18: 佣兵固伤 | C18: 佣兵固减 | D18: 佣兵增伤 | E18: 佣兵减伤 | F18: 佣兵暴击 | G18: 佣兵抗暴 | H18: 佣兵韧性 | I18: 佣兵抗韧 | J18: 全武穿透 | K18: 全武抗穿 | L18: 力量值 | M18: 速度值
A19: 属性总计 | B19: =50*5+118 | C19: =50*4+70 | D19: =0.25*6 | E19: =0.25*5 | F19: =0.25*2 | G19: =0.25*2 | H19: =0.25*6+0.2 | I19: =0.25*5 | J19: =0.05*1 | K19: =0.06*2+0.05 | L19: =20*2+12 | M19: =20*3+12
B20: 鹿仙人 | C20: 顶级扫地僧 | D20: 钢铁侠 | E20: 锦鲤仙人 | F20: 顶级令狐冲 | G20: 扫地僧 | H20: 鹤仙人 | I20: 东方不败 | J20: 经阁扫地僧 | K20: 鹅右介 | L20: 我爱鹅 | M20: 东方不败
B21: 令狐冲 | C21: 丘处机 | D21: 我爱鹅 | E21: 鹤笔翁 | F21: 八神鹅 | G21: 草薙鹅 | H21: 豆油队长 | I21: 无崖子 | J21: x | K21: 周瑜 | L21: 韦小宝 | M21: 齐天大圣
B22: 丁春秋 | C22: 赵敏 | D22: 独孤求败 | E22: 达摩祖师 | F22: x | G22: x | H22: 经阁扫地僧 | I22: 韦小宝 | J22: x | K22: 郭嘉 | L22: 御天战鹅 | M22: 无崖子
B23: 顶级韦一笑 | C23: 鹅离雨 | D23: 韦一笑 | E23: 赵云 | F23: x | G23: x | H23: 诸葛孔明 | I23: 齐天大圣 | J23: x | K23: x | L23: x | M23: 御天战鹅
B24: 鹅逍遥 | C24: 鹅右介 | D24: 黑山老妖 | E24: 山丘鹅 | F24: x | G24: x | H24: 乐斗忍者 | I24: 周瑜 | J24: x | K24: x | L24: x | M24: x
B25: 鹅斯拉 | C25: x | D25: 黄盖 | E25: x | F25: x | G25: x | H25: 鹅灵儿 | I25: x | J25: x | K25: x | L25: x | M25: x
B26: x | C26: x | D26: x | E26: x | F26: x | G26: x | H26: 御天战鹅 | I26: x | J26: x | K26: x | L26: x | M26: x
A28: 天赋消耗 | B28: 等级 | C28: 1级 | D28: 2级 | E28: 3级 | F28: 4级 | G28: 5级 | H28: 6级 | I28: 7级 | J28: 8级 | K28: 9级 | L28: 10级 | M28: 总天赋丹
A29: 佣兵天赋1 | B29: 战斗力 | C29: 10 | D29: 12 | E29: 14 | F29: 17 | G29: 20 | H29: 23 | I29: 26 | J29: 29 | K29: 32 | L29: 35 | M29: ="档次1"&CHAR(10)&SUM(C30:K30)
B30: 升级消耗 | C30: 20 | D30: 24 | E30: 28 | F30: 36 | G30: 40 | H30: 44 | I30: 48 | J30: 60 | K30: 72 | L30: x
B31: 战斗力 | C31: 20 | D31: 22 | E31: 25 | F31: 28 | G31: 32 | H31: 38 | I31: 43 | J31: 48 | K31: 54 | L31: 60 | M31: ="档次2"&CHAR(10)&SUM(C32:K32)
B32: 升级消耗 | C32: 32 | D32: 40 | E32: 48 | F32: 56 | G32: 64 | H32: 72 | I32: 80 | J32: 96 | K32: 112 | L32: x
B33: 战斗力 | C33: 20 | D33: 25 | E33: 30 | F33: 35 | G33: 40 | H33: 45 | I33: 50 | J33: 55 | K33: 60 | L33: 70 | M33: ="档次3"&CHAR(10)&SUM(C34:K34)
B34: 升级消耗 | C34: 40 | D34: 50 | E34: 60 | F34: 70 | G34: 80 | H34: 90 | I34: 100 | J34: 120 | K34: 140 | L34: x
A35: 佣兵天赋2 | B35: 战斗力 | C35: 30 | D35: 35 | E35: 40 | F35: 45 | G35: 50 | H35: 55 | I35: 60 | J35: 70 | K35: 80 | L35: 90 | M35: ="档次1"&CHAR(10)&SUM(C36:K36)
B36: 升级消耗 | C36: 54 | D36: 68 | E36: 81 | F36: 95 | G36: 108 | H36: 122 | I36: 135 | J36: 162 | K36: 189 | L36: x
B37: 战斗力 | C37: 40 | D37: 45 | E37: 50 | F37: 60 | G37: 70 | H37: 80 | I37: 90 | J37: 100 | K37: 110 | L37: 120 | M37: ="档次2"&CHAR(10)&SUM(C38:K38)
B38: 升级消耗 | C38: 72 | D38: 90 | E38: 108 | F38: 126 | G38: 144 | H38: 162 | I38: 180 | J38: 216 | K38: 252 | L38: x
B39: 战斗力 | C39: 70 | D39: 80 | E39: 90 | F39: 100 | G39: 120 | H39: 140 | I39: 160 | J39: 180 | K39: 200 | L39: 220 | M39: ="档次3"&CHAR(10)&SUM(C40:K40)
B40: 升级消耗 | C40: 136 | D40: 160 | E40: 188 | F40: 228 | G40: 286 | H40: 321 | I40: 360 | J40: 425 | K40: 504 | L40: x
B41: 战斗力 | C41: 75 | D41: 85 | E41: 100 | F41: 115 | G41: 135 | H41: 155 | I41: 175 | J41: 195 | K41: 215 | L41: 240 | M41: ="档次4"&CHAR(10)&SUM(C42:K42)
B42: 升级消耗 | C42: 144 | D42: 180 | E42: 216 | F42: 252 | G42: 288 | H42: 324 | I42: 360 | J42: 432 | K42: 504 | L42: x
...

Sheet 神将综合
A1: 神将综合 | B1: 大型武器专属神将 | E1: 中型武器专属神将 | H1: 小型武器专属神将 | K1: 投掷武器专属神将
A2: 神将月卡 | B2: 冠军炫炫 | C2: 雷神托尔 | D2: 盘古 | E2: 灭世 | F2: 帝辛 | G2: 神将天蓬 | H2: 女帝武则天 | I2: 菜菜大侠 | J2: 神将红莲 | K2: 豪华午餐 | L2: 天才樱木 | M2: 爆风9C
B3: 燕人张飞 | C3: 项羽 | D3: 海王波塞冬 | E3: 帅帅大侠 | F3: 汉皇刘邦 | G3: 神将郭靖 | H3: 诗仙李白 | I3: 嬴政 | J3: 姜子牙 | K3: 神将虚日鼠 | L3: 可乐游侠 | M3: 鹅卡西
B4: 光明圣骑士 | C4: 武圣关羽 | D4: 新春游侠 | E4: 哪吒 | F4: 神将周 | G4: 神将猎魔人 | H4: 机甲战士 | I4: 雀星宿 | J4: 小丑 | K4: 贵妃杨玉环 | L4: 神将奥丁 | M4: 幻神洛基
B5: 死亡骑士 | C5: 温侯吕布 | D5: 金毛狮王 | E5: x | F5: 熊猫潘达 | G5: 倚天剑 | H5: 死神 | I5: x | J5: x | K5: x | L5: x | M5: x
B6: 剑君大侠 | C6: x | D6: x | E6: x | F6: x | G6: x | H6: x | I6: x | J6: x | K6: x | L6: x | M6: x
A8: 神将组合 | B8: 当前共41种神将，共21种组合
A9: 名称 | B9: 百战武圣=温侯吕布+武圣关羽 | E9: 侠之大者=帅帅+菜菜+剑君 | H9: 藏龙卧虎=熊猫潘达+金毛狮王 | K9: 擎天驾海=雷神托尔+海王波塞冬
A10: 属性 | B10: 武器穿透5% | E10: 技能韧性5%、技能抗韧5% | H10: 技能暴击30%、技能暴伤50% | K10: 武器暴伤50%、武器暴减50%
A11: 名称 | B11: 毁天灭地=灭世+女帝武则天 | E11: 创世科技=盘古+机甲战士 | H11: 百鬼众魅=死神+死亡骑士 | K11: 封神之战=哪吒+姜子牙
A12: 属性 | B12: 全部增伤10%、全部暴击15% | E12: 全部抗穿5% | H12: 全部减伤10%、全部抗暴15% | K12: 技能暴减50%、武器暴击30%
A13: 名称 | B13: 楚河汉界=项羽+汉皇刘邦 | E13: 国色天香=女帝武则天+贵妃杨玉环 | H13: 黎明破晓=诗仙李白+祸乱之源小丑 | K13: 乐斗先锋=冠军炫炫+天才樱木
A14: 属性 | B14: 生命20%、力量20%、敏捷20% | E14: 武器韧性5% | H14: 武器命中5%、武器闪避5% | K14: 武器增伤5%、武器减伤5%
A15: 名称 | B15: 千古一帝=帝辛+蠃政 | E15: 动漫乱斗=鹅卡西+神将红莲 | H15: 深渊之潮=神将猎魔人+光明圣骑士 | K15: 信念传承=新春游侠+可乐游侠
A16: 属性 | B16: 技能减伤12%、技能抗暴12% | E16: 小型穿透6%、投掷穿透6% | H16: 速度12、真伤12 | K16: 武器韧性6%、技能抗韧6%
A17: 名称 | B17: 位面乱舞=雀星宿+神将天蓬 | E17: 龙飞凤舞=神将周+神将虚日鼠 | H17: 力破万钧=神将奥丁+燕人张飞 | K17: 战魂无双=神将郭靖+爆风9C
A18: 属性 | B18: 武器抗韧6%、技能韧性6% | E18: 速度10、力量10、敏捷10 | H18: 武器增伤5%、真伤12 | K18: 武器抗韧/减伤5%、技能增伤12%
A19: 名称 | B19: 神魔共舞=幻神洛基+神将？
A20: 属性 | B20: 小型抗穿6%、投掷抗穿6%、力量10
A22: 神将月卡 | B22: 1月 | C22: 2月 | D22: 3月 | E22: 4月 | F22: 5月 | G22: 6月 | H22: 7月 | I22: 8月 | J22: 9月 | K22: 10月 | L22: 11月 | M22: 12月
A23: 2021年 | B23: 狮王 | C23: 熊猫双倍 | D23: 雷神 | E23: 炫炫 | F23: 海王 | G23: 灭世双倍 | H23: 李白双倍 | I23: 雷神 | J23: 海王 | K23: 女帝双倍 | L23: 灭世 | M23: 雷神
A24: 2022年 | B24: 海王 | C24: 灭世双倍 | D24: 女帝双倍 | E24: 雷神 | F24: 灭世双倍 | G24: 女帝双倍 | H24: 雷神双倍 | I24: 海王双倍 | J24: 灭世双倍 | K24: 女帝双倍 | L24: 海王双倍 | M24: 剑君双倍
A25: 2023年 | B25: 雷神双倍 | C25: 灭世双倍 | D25: 海王双倍 | E25: 女帝双倍 | F25: 雷神双倍 | G25: 灭世双倍 | H25: 女帝双倍 | I25: 海王双倍 | J25: 雷神双倍 | K25: 灭世双倍 | L25: 女帝双倍 | M25: 海王双倍
A26: 2024年 | B26: 雷神双倍 | C26: 灭世双倍 | D26: 女帝双倍 | E26: 海王双倍 | F26: 雷神双倍 | G26: 灭世双倍 | H26: 女帝双倍 | I26: 海王双倍 | J26: 雷神双倍 | K26: 灭世双倍 | L26: 女帝双倍 | M26: 海王双倍
A27: 2025年 | B27: 雷神双倍 | C27: 灭世双倍 | D27: 女帝双倍 | E27: 吕布双倍 | F27: 关羽双倍 | G27: 灭世三倍 | H27: 女帝双倍 | I27: 海王双倍 | J27: 炫炫双倍 | K27: 关羽三倍 | L27: 灭世双倍 | M27: 雷神双倍
A28: 2026年 | B28: 雷神/灭世/女帝/海王/吕布5选2双倍(2月三倍) | F28: 新增哪吒 | G28: 6选2三倍 | H28: 6选2双倍
A30: 温侯吕布 | B30: 被动属性 | C30: 天赋点 | D30: 技能抗韧 | E30: 大型抗韧 | F30: 中型抗韧 | G30: 小型抗韧 | H30: 投掷抗韧 | I30: 武器属性-天赋分支1
A31: 专属武器 方天画戟 真·方天画戟 | B31: LV0 | C31: 1 | D31: 1% | E31: x | F31: x | G31: x | H31: x | I31: 消耗 天赋点1 | J31: 基础共鸣：增加专属武器20点基础伤害
B32: LV1 | C32: 1 | D32: 2% | E32: 1% | F32: x | G32: x | H32: x
B33: LV2 | C33: 1 | D33: 3% | E33: 1% | F33: 1% | G33: x | H33: x | I33: 消耗 天赋点2 | J33: 中级共鸣：增加专属武器30点基础伤害
B34: LV3 | C34: 3 | D34: 4% | E34: 2% | F34: 2% | G34: x | H34: x
B35: LV4 | C35: 4 | D35: 5% | E35: 3% | F35: 3% | G35: 3% | H35: x | I35: 消耗 天赋点3 | J35: 高级共鸣：增加专属武器50点基础伤害
B36: LV5 | C36: 8 | D36: 5% | E36: 5% | F36: 5% | G36: 5% | H36: 5%
A37: 碎片需求 | B37: 充能属性-战斗技能-持续整场战斗-温侯变身 | I37: 武器属性-天赋分支2
A38: 200 | B38: LV0：降低对手武器暴击伤害60%，降低对手武器吸血比例60% | I38: 消耗 天赋点1 | J38: 凶性：暴击率增加15%
A39: 150 | B39: LV1：降低对手武器暴击伤害62%，降低对手武器吸血比例62%
A40: 300 | B40: LV2：降低对手武器暴击伤害65%，降低对手武器吸血比例65% | I40: 消耗 天赋点2 | J40: 杀意：暴击伤害增加25%
A41: 500 | B41: LV3：降低对手武器暴击伤害69%，降低对手武器吸血比例69%
A42: 900 | B42: LV4：降低对手武器暴击伤害74%，降低对手武器吸血比例74% | I42: 消耗 天赋点3 | J42: 嗜血杀戮：无视对手抗暴击伤害50%
A43: 1500 | B43: LV5：降低对手武器暴击伤害80%，降低对手武器吸血比例80%
...

Sheet 武器综合
A1: 武器综合 | B1: 大型武器 | E1: 中型武器 | H1: 小型武器 | K1: 投掷武器 | N1: 打桩相关设定
A2: 武器觉醒 | B2: 祥云火炬 | C2: 雷神之锤 | D2: 盘古开天斧 | E2: 砖家之怒 | F2: 大夏龙雀 | G2: 九齿钉耙 | H2: 传说之杖 | I2: 佛跳墙 | J2: 合金钻头 | K2: 豪华午餐 | L2: 我的篮球鞋 | M2: 核弹 | N2: 破军力量 | O2: 25% | P2: 奥义次数 | Q2: 3
B3: 降妖宝杖 | C3: 盘龙之戟 | D3: 海洋之心 | E3: 龙武之魂 | F3: 龙脊 | G3: 射雕神弓 | H3: 光剑 | I3: 鸭爪叉 | J3: 钟馗道剑 | K3: 王牌飞行鼠 | L3: 可乐终结者 | M3: 螺旋手里剑 | N3: 混沌力量 | O3: 0% | P3: 奥义速度 | Q3: 100%
B4: 蒸汽重锤 | C4: 青龙偃月刀 | D4: 加特林 | E4: 穿刺之枪 | F4: 老虎凳 | G4: 双持狂战斧 | H4: 月光宝盒 | I4: 沙漠之鹰 | J4: 蛟龙水枪 | K4: 奇妙种子 | L4: 贯星长枪 | M4: 老虎鸡 | N4: 溯游敏捷 | O4: 21% | P4: 溯游速度 | Q4: 7%
B5: 死神之镰 | C5: 方天画戟 | D5: 屠龙刀 | E5: x | F5: 打狗棒 | G5: 倚天剑 | H5: 生死簿 | I5: x | J5: x | K5: x | L5: 玲珑宝塔 | M5: 缚龙仙绳 | N5: 灵动敏捷 | O5: 0% | P5: 灵动速度 | Q5: 0%
B6: 真斗战神剑 | C6: x | D6: 定海神针 | E6: 北斗七星 | F6: 圣道之剑 | G6: 死亡之翼 | H6: x | I6: 黄金酒桶 | J6: 万磁头盔 | K6: x | L6: 暴雨梨花针 | M6: 扑克王 | N6: 武器状态 | O6: 平均输出 | P6: 攻击次数 | Q6: 武器连击
A7: 强化祝福详情：1~4星必成，一部分4升5星必成，另一部分4升5星不降级（装死和封印祭坛的4把武器不参与活动）。
A8: 武器分类 | B8: 名称 | C8: 获取途径 | D8: 基础伤害 | E8: 消耗及属性（此表包含剩余所有不可觉醒的武器） | N8: 打桩计算 | O8: 暴击伤害 | P8: 增伤比例 | Q8: 附加伤害
A9: 中型武器 | B9: 霹雳鞭 | C9: 斗神塔 | D9: 20-25 | E9: 收集 5 颗1级万灵石。有 30 %的概率在攻击中附带10%的吸血效果。 | N9: 大武 | O9: 550% | P9: 350% | Q9: 1200
A10: 中型武器 | B10: 蚀骨鞭 | C10: 斗神塔 | D10: 25-30 | E10: 收集 5 颗2级万灵石。有 30 %的概率在攻击中附带15%的吸血效果。 | N10: 中武 | O10: 550% | P10: 350% | Q10: 1200
A11: 中型武器 | B11: 混元金钩 | C11: 斗神塔 | D11: 30-35 | E11: 收集 7 颗3级万灵石。有 30 %的概率在攻击中附带20%的吸血效果。 | N11: 小武 | O11: 550% | P11: 350% | Q11: 1200
A12: 中型武器 | B12: 锁魂藤 | C12: 斗神塔 | D12: 35-40 | E12: 收集10颗4级万灵石。有 30 %的概率在攻击中附带30%的吸血效果。 | N12: 投掷 | O12: 550% | P12: 350% | Q12: 1200
A13: 中型武器 | B13: 游龙惊鸿 | C13: 斗神塔 | D13: 45-50 | E13: 收集15颗5级万灵石。有 30 %的概率在攻击中附带40%的吸血效果。 | N13: 力量 | O13: 1100 | P13: 固定伤害 | Q13: 1000
A14: 中型武器 | B14: 仙人指路 | C14: 斗神塔 | D14: 60-65 | E14: 收集30颗6级万灵石。有 30 %的概率在攻击中附带60%的吸血效果。 | N14: 敏捷 | O14: 750 | P14: 真实伤害 | Q14: 100
A15: 中型武器 | B15: 雷霆万钧 | C15: 斗神塔 | D15: 63-68 | E15: 收集60颗7级万灵石。有 50 %的概率在攻击中附带60%的吸血效果，命中提升10%。 | N15: 速度 | O15: 1500 | P15: 扔武伤害 | Q15: 18%
A16: 中型武器 | B16: 五雷轰顶 | C16: 斗神塔 | D16: 65-70 | E16: 能量 3000 点以上，每日消耗288点。有 60 %的概率在攻击中附带60%的吸血效果，命中提升50%。 | N16: 生命 | O16: 15000
A17: 中型武器 | B17: 北斗七星 | C17: 斗神塔 | D17: 65-70 | E17: 能量10000点以上，每日消耗864点。有100%的概率在攻击中附带60%的吸血效果，必中。 | N17: 等级 | O17: 170
A18: 中型武器 | B18: 桃木扇 | C18: 抢地盘 | D18: 30-50 | E18: 消耗 2 个桃木扇骨兑换1天。15%的几率2.0倍暴击，命中提升10%，忽略装死，无视大海。
A19: 中型武器 | B19: 玄铁扇 | C19: 抢地盘 | D19: 35-60 | E19: 消耗 5 个玄铁扇骨兑换1天。15%的几率2.5倍暴击，命中提升15%，忽略装死，无视大海。
A20: 中型武器 | B20: 秋风孤叶扇 | C20: 抢地盘 | D20: 40-70 | E20: 消耗10个孤叶扇骨兑换1天。15%的几率3.0倍暴击，命中提升20%，忽略装死，无视大海。
A21: 投掷武器 | B21: 新春鞭炮 | C21: 春节充能 | D21: 50-50 | E21: 节日消耗20时之沙充能1天。优先选中，必中，暴击概率50%，忽略1回合。
A22: 小型武器 | B22: 劳动节扫把 | C22: 五一充能 | D22: 50-50 | E22: 节日消耗20时之沙充能1天。优先选中，必中，连击概率50%，忽略1回合。
A23: 小型武器 | B23: 乐斗拳套 | C23: 周年充能 | D23: 50-50 | E23: 节日消耗20时之沙充能1天。优先选中，必中，伤害提升50%，忽略1回合。
A24: 中型武器 | B24: 冰镇西瓜 | C24: 八月充能 | D24: 50-50 | E24: 活动消耗20时之沙充能1天。优先选中，必中，降低对手力量80%持续3回合，忽略1回合。
A25: 小型武器 | B25: 圣诞棒棒糖 | C25: 圣诞充能 | D25: 50-50 | E25: 节日消耗20时之沙充能1天。优先选中，必中，附带对手当前生命10%的额外伤害，忽略1回合。
A26: 大型武器 | B26: 邪·霸皇 | C26: 许愿帮铺 | D26: 75-95 | E26: 消耗129许愿点。优先选中，必中，必暴击，无视反弹，15%忽略1回合。神技同神·霸皇。
A27: 中型武器 | B27: 魔·命运枪 | C27: 许愿帮铺 | D27: 75-95 | E27: 消耗119许愿点。优先选中，100%连击，忽略装死、皮糙，命中暴击提升30%持续3回合。神技同神·命运之枪。
A28: 小型武器 | B28: 幻·月光炮 | C28: 许愿帮铺 | D28: 75-85 | E28: 消耗109许愿点。优先选中，必中，必暴击，无视大海、霸气，忽略1回合，伤害提升80%。神技同神·月光炮。
A29: 投掷武器 | B29: 灵·霸天鼠 | C29: 许愿帮铺 | D29: 55-85 | E29: 消耗 99许愿点。优先选中，必中，降低对手闪避50%持续2回合。神技同神·霸天鼠。
... A43: 大型武器 | B43: 真·方天画戟 | C43: 消费排行 | D43: 75-100 | E43: 必中，忽略装死，不会被反击，无视反弹、霸气，忽略2回合，下回合攻击必中。
A45: 武器觉醒 | B45: 条目 | C45: 0阶 | D45: 1阶 | E45: 2阶 | F45: 3阶 | G45: 4阶 | H45: 5阶 | I45: 6阶 | J45: 7阶 | K45: 8阶 | L45: 9阶 | M45: 10阶
A46: 百炼钢 觉醒档次1 | B46: 战斗力 | C46: 0 | D46: 0.1 | E46: 0.3 | F46: 0.5 | G46: 1.4 | H46: 1.9 | I46: 2.5 | J46: 4.8 | K46: 5.9 | L46: 7.2 | M46: 9
B47: 祝福值 | C47: 4 | D47: 6 | E47: 16 | F47: 28 | G47: 44 | H47: 62 | I47: 80 | J47: 100 | K47: 132 | L47: 200 | M47: x
B48: 单次材料 | C48: 1 | D48: 2 | E48: 3 | F48: 4 | G48: 5 | H48: 6 | I48: 7 | J48: 8 | K48: 10 | L48: 12 | M48: 材料总计
B49: 满祝材料 | C49: =ROUNDUP((C47/2+1),0)*C48 | D49: =ROUNDUP((D47/2+1),0)*D48 | E49: =ROUNDUP((E47/2+1),0)*E48 | F49: =ROUNDUP((F47/2+1),0)*F48 | G49: =ROUNDUP((G47/2+1),0)*G48 | H49: =ROUNDUP((H47/2+1),0)*H48 | I49: =ROUNDUP((I47/2+1),0)*I48 | J49: =ROUNDUP((J47/2+1),0)*J48 | ... L49: =ROUNDUP((L47/2+1),0)*L48 | M49: =SUM(B49:L49)
A50: 淬火结晶 觉醒档次1 | B50: 战斗力 | C50: 0 | D50: 0.1 | E50: 0.3 | F50: 0.5 | G50: 1.7 | H50: 2.3 | I50: 3 | J50: 5.8 | K50: 7 | L50: 8.6 | M50: 10.8
B51: 祝福值 | C51: 4 | D51: 6 | E51: 10 | F51: 22 | G51: 36 | H51: 46 | I51: 66 | J51: 80 | K51: 100 | L51: 132 | M51: x
B52: 单次材料 | C52: 1 | D52: 2 | E52: 3 | F52: 4 | G52: 5 | H52: 6 | I52: 7 | J52: 8 | K52: 9 | L52: 10 | M52: 材料总计
B53: 满祝材料 | C53: =ROUNDUP((C51/2+1),0)*C52 | D53: =ROUNDUP((D51/2+1),0)*D52 | E53: =ROUNDUP((E51/2+1),0)*E52 | F53: =ROUNDUP((F51/2+1),0)*F52 | G53: =ROUNDUP((G51/2+1),0)*G52 | H53: =ROUNDUP((H51/2+1),0)*H52 | I53: =ROUNDUP((I51/2+1),0)*I52 | J53: =ROUNDUP((J51/2+1),0)*J52 | ... L53: =ROUNDUP((L51/2+1),0)*L52 | M53: =SUM(B53:L53)
A54: 淬火结晶 觉醒档次2 | B54: 战斗力 | C54: 0 | D54: 0.1 | E54: 0.3 | F54: 0.6 | G54: 1.9 | H54: 2.5 | I54: 3.3 | J54: 6.4 | K54: 7.8 | L54: 9.6 | M54: 12
...

Sheet 门派心法
A1: 门派心法 | B1: 名称 | C1: 基础1 | D1: 基础2 | E1: 基础3 | F1: 上层1 | G1: 上层2 | H1: 上层3 | I1: 上层4 | J1: 上层5 | K1: 上层6 | L1: 祝福详情：进度模式，永久有效。 | S1: =首页索引!$M$1 | T1: 1
A2: 基础心法 门派贡献 上层心法 炼气石 | B2: 少林 | C2: 法华经 | D2: 金刚经 | E2: 达摩心经 | F2: 金刚伏魔 | G2: 金刚护法 | H2: 佛光万丈 | I2: 大光明经 | J2: 达摩护体 | K2: 万佛朝宗 | L2: 常规祝福：上层心法固定1点进度值，25级前（含）可能暴击获得2/5点进度值。炼气石120斗豆。
B3: 华山 | C3: 御剑术 | D3: 龟息术 | E3: 养心术 | F3: 清风剑法 | G3: 抱元劲 | H3: 冰心诀 | I3: 狂风快剑 | J3: 混元功 | K3: 紫气天罗 | L3: 春节祝福：上层心法固定1点进度值，28级前（含）可能暴击获得2/5点进度值。炼气石100斗豆。
B4: 峨眉 | C4: 斩情诀 | D4: 护心诀 | E4: 观音咒 | F4: 灵心咒 | G4: 神佑经 | H4: 延年益寿 | I4: 九阴真经 | J4: 坐怀不乱 | K4: 清心普善 | L4: 周年祝福：上层心法固定1点进度值，30级前（含）可能暴击获得2/5点进度值。炼气石100斗豆。
B5: 丐帮 | C5: 醉拳 | D5: 烟雨行 | E5: 笑尘诀 | F5: 打狗棒法 | G5: 空冥诀 | H5: 逍遥游 | I5: 降龙掌法 | J5: 擒龙功 | K5: 玉阳神功 | L5: 中秋祝福：上层心法固定1点进度值，30级前（含）可能暴击获得2/5点进度值。炼气石200斗豆。
B6: 武当 | C6: 太极内力 | D6: 绕指柔剑 | E6: 金丹秘诀 | F6: 两仪心法 | G6: 混元一气 | H6: 仙人指路 | I6: 揽雀尾 | J6: 洗髓金经 | K6: 纯阳无极 | L6: 由于暴击情况不太稳定，差异较大，为方便计算，表内消耗数据均按照无暴击计算。 基础心法均满级后，门贡无用，勿再花费门派战书打额外邀请赛和同门切磋（需凑活跃时除外）。
B7: 明教 | C7: 圣火功 | D7: 五行阵 | E7: 日月凌天 | F7: 逍遥乾坤 | G7: 吸引神魔 | H7: 横空挪移 | I7: 乾坤归一 | J7: 无极心法 | K7: 无明业火
A8: 名称 | B8: 等级 | C8: 战斗力 | D8: 进度值 | E8: 单次材料 | F8: 满值材料 | G8: 生命值 | H8: 命中率 | I8: 闪避率 | J8: 暴击率 | K8: 抗暴率 | L8: 武器附伤 | M8: 武器附减 | N8: 技空附伤 | O8: 技空附减 | P8: 门武增伤 | Q8: 门武减伤 | R8: 门技增伤 | S8: 门技减伤
A9: 少林 基础心法 法华经 | B9: 1 | C9: 0.2 | D9: 10 | E9: 20 | F9: =D9*E9 | G9: 1 | H9: 0% | I9: x | J9: 0% | K9: x | L9: 0 | M9: x | N9: 0 | O9: x | P9: 0.5% | Q9: x | R9: x | S9: x
B10: 2 | C10: 0.4 | D10: 10 | E10: 20 | F10: =D10*E10 | G10: 1 | H10: 0.1% | I10: x | J10: 0.1% | K10: x | L10: 0 | M10: x | N10: 0 | O10: x | P10: 1% | Q10: x | R10: x | S10: x
B11: 3 | C11: 0.6 | D11: 10 | E11: 20 | F11: =D11*E11 | G11: 2 | H11: 0.1% | I11: x | J11: 0.1% | K11: x | L11: 0 | M11: x | N11: 0 | O11: x | P11: 1.5% | Q11: x | R11: x | S11: x
B12: 4 | C12: 0.7 | D12: 10 | E12: 20 | F12: =D12*E12 | G12: 2 | H12: 0.1% | I12: x | J12: 0.1% | K12: x | L12: 0 | M12: x | N12: 0 | O12: x | P12: 2% | Q12: x | R12: x | S12: x
B13: 5 | C13: 1.4 | D13: 10 | E13: 20 | F13: =D13*E13 | G13: 3 | H13: 0.2% | I13: x | J13: 0.2% | K13: x | L13: 1 | M13: x | N13: 0 | O13: x | P13: 2.5% | Q13: x | R13: x | S13: x
B14: 6 | C14: 1.6 | D14: 12 | E14: 30 | F14: =D14*E14 | G14: 3 | H14: 0.2% | I14: x | J14: 0.2% | K14: x | L14: 1 | M14: x | N14: 0 | O14: x | P14: 3.3% | Q14: x | R14: x | S14: x
B15: 7 | C15: 2 | D15: 12 | E15: 30 | F15: =D15*E15 | G15: 4 | H15: 0.3% | I15: x | J15: 0.3% | K15: x | L15: 1 | M15: x | N15: 0 | O15: x | P15: 4% | Q15: x | R15: x | S15: x
B16: 8 | C16: 2.4 | D16: 12 | E16: 30 | F16: =D16*E16 | G16: 5 | H16: 0.3% | I16: x | J16: 0.3% | K16: x | L16: 1 | M16: x | N16: 1 | O16: x | P16: 4.8% | Q16: x | R16: x | S16: x
B17: 9 | C17: 2.8 | D17: 12 | E17: 30 | F17: =D17*E17 | G17: 6 | H17: 0.4% | I17: x | J17: 0.4% | K17: x | L17: 1 | M17: x | N17: 1 | O17: x | P17: 5.5% | Q17: x | R17: x | S17: x
B18: 10 | C18: 3.2 | D18: 12 | E18: 30 | F18: =D18*E18 | G18: 7 | H18: 0.5% | I18: x | J18: 0.5% | K18: x | L18: 1 | M18: x | N18: 1 | O18: x | P18: 6.3% | Q18: x | R18: x | S18: x
B19: 11 | C19: 3.9 | D19: 14 | E19: 50 | F19: =D19*E19 | G19: 8 | H19: 0.5% | I19: x | J19: 0.5% | K19: x | L19: 2 | M19: x | N19: 1 | O19: x | P19: 7.3% | Q19: x | R19: x | S19: x
B20: 12 | C20: 4.3 | D20: 14 | E20: 50 | F20: =D20*E20 | G20: 9 | H20: 0.6% | I20: x | J20: 0.6% | K20: x | L20: 2 | M20: x | N20: 1 | O20: x | P20: 8.3% | Q20: x | R20: x | S20: x
B21: 13 | C21: 4.7 | D21: 14 | E21: 50 | F21: =D21*E21 | G21: 10 | H21: 0.7% | I21: x | J21: 0.7% | K21: x | L21: 2 | M21: x | N21: 1 | O21: x | P21: 9.3% | Q21: x | R21: x | S21: x
... B43: 35 | C43: 37.9 | D43: 30 | E43: 150 | F43: =D43*E43 | G43: 78 | H43: 5.4% | I43: x | J43: 5.4% | K43: x | L43: 17 | M43: x | N43: 9 | O43: x | P43: 75% | Q43: x | R43: x | S43: x
A44: 少林 基础心法 金刚经 | B44: 1 | C44: 0.3 | D44: 10 | E44: 20 | F44: =D44*E44 | G44: 1 | H44: x | I44: 0% | J44: x | K44: 0.1% | L44: x | M44: 0 | N44: x | O44: 0 | P44: x | Q44: 0.5% | R44: x | S44: x
B45: 2 | C45: 0.5 | D45: 10 | E45: 20 | F45: =D45*E45 | G45: 1 | H45: x | I45: 0.1% | J45: x | K45: 0.2% | L45: x | M45: 0 | N45: x | O45: 0 | P45: x | Q45: 1% | R45: x | S45: x
B46: 3 | C46: 1.3 | D46: 10 | E46: 20 | F46: =D46*E46 | G46: 2 | H46: x | I46: 0.1% | J46: x | K46: 0.3% | L46: x | M46: 1 | N46: x | O46: 1 | P46: x | Q46: 1.5% | R46: x | S46: x
B47: 4 | C47: 1.5 | D47: 10 | E47: 20 | F47: =D47*E47 | G47: 2 | H47: x | I47: 0.1% | J47: x | K47: 0.4% | L47: x | M47: 1 | N47: x | O47: 1 | P47: x | Q47: 2% | R47: x | S47: x
B48: 5 | C48: 1.8 | D48: 10 | E48: 20 | F48: =D48*E48 | G48: 3 | H48: x | I48: 0.2% | J48: x | K48: 0.5% | L48: x | M48: 1 | N48: x | O48: 1 | P48: x | Q48: 2.5% | R48: x | S48: x
B49: 6 | C49: 2 | D49: 12 | E49: 30 | F49: =D49*E49 | G49: 3 | H49: x | I49: 0.2% | J49: x | K49: 0.6% | L49: x | M49: 1 | N49: x | O49: 1 | P49: x | Q49: 3.3% | R49: x | S49: x
B50: 7 | C50: 3.1 | D50: 12 | E50: 30 | F50: =D50*E50 | G50: 4 | H50: x | I50: 0.3% | J50: x | K50: 0.8% | L50: x | M50: 2 | N50: x | O50: 2 | P50: x | Q50: 4% | R50: x | S50: x
B51: 8 | C51: 3.4 | D51: 12 | E51: 30 | F51: =D51*E51 | G51: 5 | H51: x | I51: 0.3% | J51: x | K51: 0.9% | L51: x | M51: 2 | N51: x | O51: 2 | P51: x | Q51: 4.8% | R51: x | S51: x
B52: 9 | C52: 3.8 | D52: 12 | E52: 30 | F52: =D52*E52 | G52: 6 | H52: x | I52: 0.4% | J52: x | K52: 1.1% | L52: x | M52: 2 | N52: x | O52: 2 | P52: x | Q52: 5.5% | R52: x | S52: x
B53: 10 | C53: 4.8 | D53: 12 | E53: 30 | F53: =D53*E53 | G53: 7 | H53: x | I53: 0.5% | J53: x | K53: 1.2% | L53: x | M53: 3 | N53: x | O53: 3 | P53: x | Q53: 6.3% | R53: x | S53: x
B54: 11 | C54: 5.2 | D54: 14 | E54: 50 | F54: =D54*E54 | G54: 8 | H54: x | I54: 0.5% | J54: x | K54: 1.4% | L54: x | M54: 3 | N54: x | O54: 3 | P54: x | Q54: 7.3% | R54: x | S54: x
B55: 12 | C55: 5.7 | D55: 14 | E55: 50 | F55: =D55*E55 | G55: 9 | H55: x | I55: 0.6% | J55: x | K55: 1.6% | L55: x | M55: 3 | N55: x | O55: 3 | P55: x | Q55: 8.3% | R55: x | S55: x
B56: 13 | C56: 6.8 | D56: 14 | E56: 50 | F56: =D56*E56 | G56: 10 | H56: x | I56: 0.7% | J56: x | K56: 1.8% | L56: x | M56: 4 | N56: x | O56: 4 | P56: x | Q56: 9.3% | R56: x | S56: x
... B78: 35 | C78: 53.9 | D78: 30 | E78: 150 | F78: =D78*E78 | G78: 78 | H78: x | I78: 5.4% | J78: x | K78: 14.4% | L78: x | M78: 32 | N78: x | O78: 32 | P78: x | Q78: 75% | R78: x | S78: x
A79: 少林 基础心法 达摩心经 | B79: 1 | C79: 0.1 | D79: 10 | E79: 20 | F79: =D79*E79 | G79: x | H79: x | I79: x | J79: x | K79: x | L79: 0 | M79: 0 | N79: 0 | O79: 0 | P79: 0.1% | Q79: x | R79: x | S79: x
B80: 2 | C80: 0.3 | D80: 10 | E80: 20 | F80: =D80*E80 | G80: x | H80: x | I80: x | J80: x | K80: x | L80: 0 | M80: 0 | N80: 0 | O80: 0 | P80: 0.2% | Q80: x | R80: x | S80: x
B81: 3 | C81: 0.5 | D81: 10 | E81: 20 | F81: =D81*E81 | G81: x | H81: x | I81: x | J81: x | K81: x | L81: 0 | M81: 1 | N81: 0 | O81: 1 | P81: 0.3% | Q81: x | R81: x | S81: x
B82: 4 | C82: 0.7 | D82: 10 | E82: 20 | F82: =D82*E82 | G82: x | H82: x | I82: x | J82: x | K82: x | L82: 0 | M82: 1 | N82: 0 | O82: 1 | P82: 0.4% | Q82: x | R82: x | S82: x
...

Sheet 门派武技
A1: 门武门技 | B1: 名称 | C1: 门武1 | D1: 门武2 | E1: 门技1 | F1: 门技2 | G1: 门技3 | H1: 门技4 | I1: 祝福详情：祝福模式，永久有效。 | O1: =首页索引!$M$1 | P1: =@IF(O1="中秋祝福",6,IF(O1="周年祝福",5,IF(O1="春节祝福",5,4)))
A2: 门派强化书 | B2: 少林 | C2: 九龙禅杖 | D2: 琉璃戒刀 | E2: 大力金刚掌 | F2: 罗汉金身 | G2: 慈航普渡 | H2: 铁头功 | I2: 常规祝福：门派武器技能失败4点祝福值。门派强化书120斗豆。
B3: 华山 | C3: 绝世好剑 | D3: 干将莫邪 | E3: 万剑归宗 | F3: 华山剑阵 | G3: 紫霞神功 | H3: 冲灵剑法 | I3: 春节祝福：门派武器技能失败5点祝福值。门派强化书100斗豆。
B4: 峨眉 | C4: 拂尘若梦 | D4: 蝶舞双刺 | E4: 清心普善咒 | F4: 玉女心经 | G4: 金针渡劫 | H4: 九阴神爪 | I4: 周年祝福：门派武器技能失败5点祝福值。门派强化书100斗豆。
B5: 丐帮 | C5: 老祖葫芦 | D5: 九袋神杖 | E5: 降龙十八掌 | F5: 玉阳神功 | G5: 笑醉狂 | H5: 游龙缠身 | I5: 中秋祝福：门派武器技能失败6点祝福值。门派强化书200斗豆。
B6: 武当 | C6: 天罡飞剑 | D6: 九天雷火 | E6: 太极剑法 | F6: 九宫八卦阵 | G6: 纵云梯 | H6: 白鹤亮翅 | I6: 门武门技均满级后，强化书无用，勿再花费门派高香（尚缺门贡时除外）。
B7: 明教 | C7: 圣火凤凰 | D7: 光明怜世 | E7: 明尊圣火功 | F7: 九阳真经 | G7: 圣火焚身 | H7: 斗转星移
A8: 名称 | B8: 等级 | C8: 战斗力 | D8: 祝福值 | E8: 单次材料 | F8: 满值材料 | G8: 效果说明
A9: 少林门武 少林棍 五级更名 降魔杵 十级更名 九龙禅杖 | B9: 0 | C9: 3 | D9: 4 | E9: 1 | F9: =ROUNDUP(D9/$P$1+1,0)*E9 | G9: 伤害： 35 ~ 65 ，每次使用大型武器后有 30 %概率触发，必中！
B10: 1 | C10: 3.7 | D10: 12 | E10: 2 | F10: =ROUNDUP(D10/$P$1+1,0)*E10 | G10: 伤害： 43 ~ 73 ，每次使用大型武器后有 31 %概率触发，必中！
B11: 2 | C11: 4.3 | D11: 24 | E11: 3 | F11: =ROUNDUP(D11/$P$1+1,0)*E11 | G11: 伤害： 51 ~ 81 ，每次使用大型武器后有 32 %概率触发，必中！
B12: 3 | C12: 5.2 | D12: 38 | E12: 4 | F12: =ROUNDUP(D12/$P$1+1,0)*E12 | G12: 伤害： 61 ~ 91 ，每次使用大型武器后有 34 %概率触发，必中！
B13: 4 | C13: 6.3 | D13: 48 | E13: 5 | F13: =ROUNDUP(D13/$P$1+1,0)*E13 | G13: 伤害： 75 ~105，每次使用大型武器后有 36 %概率触发，必中！
B14: 5 | C14: 9.2 | D14: 54 | E14: 6 | F14: =ROUNDUP(D14/$P$1+1,0)*E14 | G14: 伤害：109~139，每次使用大型武器后有 38 %概率触发，必中！增加自身生命值 13
B15: 6 | C15: 10.4 | D15: 60 | E15: 7 | F15: =ROUNDUP(D15/$P$1+1,0)*E15 | G15: 伤害：124~154，每次使用大型武器后有 41 %概率触发，必中！增加自身生命值 17
B16: 7 | C16: 11.7 | D16: 70 | E16: 8 | F16: =ROUNDUP(D16/$P$1+1,0)*E16 | G16: 伤害：139~169，每次使用大型武器后有 44 %概率触发，必中！增加自身生命值 22
B17: 8 | C17: 13.5 | D17: 80 | E17: 9 | F17: =ROUNDUP(D17/$P$1+1,0)*E17 | G17: 伤害：161~191，每次使用大型武器后有 48 %概率触发，必中！增加自身生命值 28
B18: 9 | C18: 15.7 | D18: 100 | E18: 10 | F18: =ROUNDUP(D18/$P$1+1,0)*E18 | G18: 伤害：187~217，每次使用大型武器后有 52 %概率触发，必中！增加自身生命值 35
B19: 10 | C19: 23.2 | D19: 110 | E19: 12 | F19: =ROUNDUP(D19/$P$1+1,0)*E19 | G19: 伤害：277~307，每次使用大型武器后有 58 %概率触发，必中！增加自身生命值 44 ，大型武器附加伤害14
B20: 11 | C20: 26.3 | D20: 120 | E20: 14 | F20: =ROUNDUP(D20/$P$1+1,0)*E20 | G20: 伤害：315~345，每次使用大型武器后有 64 %概率触发，必中！增加自身生命值 53 ，大型武器附加伤害17
B21: 12 | C21: 29.7 | D21: 140 | E21: 16 | F21: =ROUNDUP(D21/$P$1+1,0)*E21 | G21: 伤害：355~385，每次使用大型武器后有 71 %概率触发，必中！增加自身生命值 65 ，大型武器附加伤害21
... B23: 14 | C23: 38 | D23: 240 | E23: 20 | F23: =ROUNDUP(D23/$P$1+1,0)*E23 | G23: 伤害：455~485，每次使用大型武器后有 89 %概率触发，必中！增加自身生命值 93 ，大型武器附加伤害30
B24: 15 | C24: 43 | D24: x | E24: x | F24: x | G24: 伤害：515~545，每次使用大型武器后有100%概率触发，必中！增加自身生命值110，大型武器附加伤害35
A25: 少林门武 少林戒刀 五级更名 镔铁雪花刀 十级更名 琉璃戒刀 | B25: 0 | C25: 3 | D25: 4 | E25: 1 | F25: =ROUNDUP(D25/$P$1+1,0)*E25 | G25: 伤害： 52 ~ 80 ，每次使用中型武器后有 30 %概率触发，必中！
B26: 1 | C26: 3.7 | D26: 14 | E26: 2 | F26: =ROUNDUP(D26/$P$1+1,0)*E26 | G26: 伤害： 62 ~ 90 ，每次使用中型武器后有 31 %概率触发，必中！
B27: 2 | C27: 4.7 | D27: 28 | E27: 3 | F27: =ROUNDUP(D27/$P$1+1,0)*E27 | G27: 伤害： 72 ~100，每次使用中型武器后有 32 %概率触发，必中！
B28: 3 | C28: 5.9 | D28: 46 | E28: 4 | F28: =ROUNDUP(D28/$P$1+1,0)*E28 | G28: 伤害： 87 ~115，每次使用中型武器后有 34 %概率触发，必中！
B29: 4 | C29: 7.3 | D29: 58 | E29: 5 | F29: =ROUNDUP(D29/$P$1+1,0)*E29 | G29: 伤害：104~132，每次使用中型武器后有 36 %概率触发，必中！
B30: 5 | C30: 11 | D30: 54 | E30: 6 | F30: =ROUNDUP(D30/$P$1+1,0)*E30 | G30: 伤害：148~176，每次使用中型武器后有 38 %概率触发，必中！增加自身命中率 3.5 %
B31: 6 | C31: 12.6 | D31: 72 | E31: 7 | F31: =ROUNDUP(D31/$P$1+1,0)*E31 | G31: 伤害：167~195，每次使用中型武器后有 41 %概率触发，必中！增加自身命中率 4.6 %
B32: 7 | C32: 14.3 | D32: 70 | E32: 8 | F32: =ROUNDUP(D32/$P$1+1,0)*E32 | G32: 伤害：188~216，每次使用中型武器后有 44 %概率触发，必中！增加自身命中率 5.9 %
B33: 8 | C33: 16.7 | D33: 96 | E33: 9 | F33: =ROUNDUP(D33/$P$1+1,0)*E33 | G33: 伤害：216~244，每次使用中型武器后有 48 %概率触发，必中！增加自身命中率 7.6 %
B34: 9 | C34: 19.6 | D34: 100 | E34: 10 | F34: =ROUNDUP(D34/$P$1+1,0)*E34 | G34: 伤害：251~279，每次使用中型武器后有 52 %概率触发，必中！增加自身命中率 9.6 %
B35: 10 | C35: 29.3 | D35: 110 | E35: 12 | F35: =ROUNDUP(D35/$P$1+1,0)*E35 | G35: 伤害：368~396，每次使用中型武器后有 58 %概率触发，必中！增加自身命中率11.9%，中型武器附加伤害14
B36: 11 | C36: 33.3 | D36: 144 | E36: 14 | F36: =ROUNDUP(D36/$P$1+1,0)*E36 | G36: 伤害：417~445，每次使用中型武器后有 64 %概率触发，必中！增加自身命中率14.5%，中型武器附加伤害17
B37: 12 | C37: 37.7 | D37: 140 | E37: 16 | F37: =ROUNDUP(D37/$P$1+1,0)*E37 | G37: 伤害：468~496，每次使用中型武器后有 71 %概率触发，必中！增加自身命中率17.6%，中型武器附加伤害21
... B39: 14 | C39: 48.6 | D39: 288 | E39: 20 | F39: =ROUNDUP(D39/$P$1+1,0)*E39 | G39: 伤害：599~627，每次使用中型武器后有 89 %概率触发，必中！增加自身命中率25.4%，中型武器附加伤害30
B40: 15 | C40: 55 | D40: x | E40: x | F40: x | G40: 伤害：676~704，每次使用中型武器后有100%概率触发，必中！增加自身命中率30.0%，中型武器附加伤害35
A41: 少林门技 大力金刚掌 | B41: 0 | C41: 3 | D41: 4 | E41: 1 | F41: =ROUNDUP(D41/$P$1+1,0)*E41 | G41: 20%概率触发，触发1次，必中！造成 12 点+自身生命上限3%的伤害值。
B42: 1 | C42: 3.7 | D42: 12 | E42: 2 | F42: =ROUNDUP(D42/$P$1+1,0)*E42 | G42: 20%概率触发，触发1次，必中！造成 14 点+自身生命上限3%的伤害值。
...

Sheet 神装神技
A1: 神装神技 | B1: 神装名称 | C1: 三阶技能 | D1: 六阶技能 | E1: 八阶技能 | F1: 祝福详情：神装等级祝福模式，永久有效。神装技能强化模式。 | M1: =首页索引!$M$1 | N1: =@IF(M1="中秋祝福",8,IF(M1="周年祝福",6,IF(M1="春节祝福",6,6)))
A2: 神兵原石 软猥金丝 凤凰羽毛 潜能果实 上古玉髓 奔流气息 神秘精华 | B2: 神兵 | C2: 神武之力 | D2: 断筋 | E2: 召唤神兵 | F2: 常规祝福：神装等级失败6点祝福值。技能7级前（含）必成，其余消耗少2个。材料120斗豆/斗币。
B3: 神铠 | C3: 圣盾术 | D3: 荆棘护甲 | E3: 无懈可击 | F3: 春节祝福：神装等级失败6点祝福值。技能7级前（含）必成，其余消耗少2个。材料100斗豆/斗币。
B4: 神羽 | C4: 惩击 | D4: 圣洁之躯 | E4: 愈合祷言 | F4: 周年祝福：神装等级失败6点祝福值。技能7级前（含）必成，其余消耗少2个。材料100斗豆/斗币。
B5: 神兽 | C5: 龟甲术 | D5: 重伤之爪 | E5: 蛮力猛击 | F5: 中秋祝福：神装等级失败8点祝福值。技能7级前（含）必成，其余消耗少3个。材料200斗豆/斗币。
B6: 神饰 | C6: 利刃 | D6: 皇族血统 | E6: 吸血咒 | F6: 神装套装：进度模式，永久有效，暂无活动。进度值随机1/2/5/10，神装之灵200斗豆。 满值材料按平均值2点计算。
B7: 神履 | C7: 蓄势待发 | D7: 足下生根 | E7: 迷踪步
A9: 神兵 | B9: 战斗力 | C9: 祝福值 | D9: 单次材料 | E9: 满值材料 | F9: 名称 | G9: 小投附伤 | H9: 大型附伤 | I9: 中型附伤 | J9: 生命值 | K9: 命中率 | L9: 摄魂战力 | M9: 摄魂数量
A10: 一阶 | B10: 1.5 | C10: 66 | D10: 1 | E10: =ROUNDUP(C10/$N$1+1,0)*D10 | F10: 青锋剑 | G10: 2 | H10: x | I10: x | J10: x | K10: x | L10: x | M10: x
A11: 二阶 | B11: 4 | C11: 66 | D11: 2 | E11: =ROUNDUP(C11/$N$1+1,0)*D11 | F11: 天下剑 | G11: 4 | H11: 4 | I11: x | J11: x | K11: x | L11: x | M11: x
A12: 三阶 | B12: 8 | C12: 100 | D12: 3 | E12: =ROUNDUP(C12/$N$1+1,0)*D12 | F12: 无双剑 | G12: 8 | H12: 8 | I12: 8 | J12: x | K12: x | L12: x | M12: x
A13: 四阶 | B13: 15 | C13: 200 | D13: 4 | E13: =ROUNDUP(C13/$N$1+1,0)*D13 | F13: 火磷剑 | G13: 12 | H13: 12 | I13: 12 | J13: 8 | K13: x | L13: x | M13: x
A14: 五阶 | B14: 24 | C14: 333 | D14: 6 | E14: =ROUNDUP(C14/$N$1+1,0)*D14 | F14: 惊寂刀 | G14: 16 | H14: 16 | I14: 16 | J14: 15 | K14: 7% | L14: =M14*0.2 | M14: 10
A15: 六阶 | B15: 32 | C15: 666 | D15: 8 | E15: =ROUNDUP(C15/$N$1+1,0)*D15 | F15: 天刃刀 | G15: 22 | H15: 22 | I15: 22 | J15: 24 | K15: 9% | L15: =M15*0.2 | M15: 20
A16: 七阶 | B16: 40 | C16: 1000 | D16: 10 | E16: =ROUNDUP(C16/$N$1+1,0)*D16 | F16: 贪狼剑 | G16: 28 | H16: 28 | I16: 28 | J16: 35 | K16: 11% | L16: =M16*0.2 | M16: 40
A17: 八阶 | B17: 48 | C17: 2000 | D17: 12 | E17: =ROUNDUP(C17/$N$1+1,0)*D17 | F17: 英雄剑 | G17: 34 | H17: 34 | I17: 34 | J17: 48 | K17: 13% | L17: =M17*0.2 | M17: 60
A18: 九阶 | B18: 60 | C18: 2000 | D18: 12 | E18: =ROUNDUP(C18/$N$1+1,0)*D18 | F18: 血饮狂刀 | G18: 40 | H18: 40 | I18: 40 | J18: 63 | K18: 15% | L18: =M18*0.2 | M18: 80
A19: 十阶 | B19: 80 | C19: x | D19: x | E19: x | F19: 绝世好剑 | G19: 50 | H19: 50 | I19: 50 | J19: 80 | K19: 18% | L19: =M19*0.2 | M19: 200
A21: 神铠 | B21: 战斗力 | C21: 祝福值 | D21: 单次材料 | E21: 满值材料 | F21: 名称 | G21: 小投附减 | H21: 大型附减 | I21: 中型附减 | J21: 生命值 | K21: 闪避率 | L21: 摄魂战力 | M21: 摄魂数量
A22: 一阶 | B22: 1.5 | C22: 66 | D22: 1 | E22: =ROUNDUP(C22/$N$1+1,0)*D22 | F22: 鳞甲 | G22: 2 | H22: x | I22: x | J22: x | K22: x | L22: x | M22: x
A23: 二阶 | B23: 4 | C23: 66 | D23: 2 | E23: =ROUNDUP(C23/$N$1+1,0)*D23 | F23: 锁子甲 | G23: 4 | H23: 4 | I23: x | J23: x | K23: x | L23: x | M23: x
A24: 三阶 | B24: 8 | C24: 100 | D24: 3 | E24: =ROUNDUP(C24/$N$1+1,0)*D24 | F24: 寒钢甲 | G24: 8 | H24: 8 | I24: 8 | J24: x | K24: x | L24: x | M24: x
A25: 四阶 | B25: 15 | C25: 200 | D25: 4 | E25: =ROUNDUP(C25/$N$1+1,0)*D25 | F25: 龙骨甲 | G25: 12 | H25: 12 | I25: 12 | J25: 8 | K25: x | L25: x | M25: x
A26: 五阶 | B26: 24 | C26: 333 | D26: 6 | E26: =ROUNDUP(C26/$N$1+1,0)*D26 | F26: 金蚕披风 | G26: 16 | H26: 16 | I26: 16 | J26: 15 | K26: 7% | L26: =M26*0.2 | M26: 10
A27: 六阶 | B27: 32 | C27: 666 | D27: 8 | E27: =ROUNDUP(C27/$N$1+1,0)*D27 | F27: 乾坤护心甲 | G27: 22 | H27: 22 | I27: 22 | J27: 24 | K27: 9% | L27: =M27*0.2 | M27: 20
A28: 七阶 | B28: 40 | C28: 1000 | D28: 10 | E28: =ROUNDUP(C28/$N$1+1,0)*D28 | F28: 蝉翼金丝甲 | G28: 28 | H28: 28 | I28: 28 | J28: 35 | K28: 11% | L28: =M28*0.2 | M28: 40
A29: 八阶 | B29: 48 | C29: 2000 | D29: 12 | E29: =ROUNDUP(C29/$N$1+1,0)*D29 | F29: 金丝鱼鳞甲 | G29: 34 | H29: 34 | I29: 34 | J29: 48 | K29: 13% | L29: =M29*0.2 | M29: 60
A30: 九阶 | B30: 60 | C30: 2000 | D30: 12 | E30: =ROUNDUP(C30/$N$1+1,0)*D30 | F30: 紫金磐龙甲 | G30: 40 | H30: 40 | I30: 40 | J30: 63 | K30: 15% | L30: =M30*0.2 | M30: 80
A31: 十阶 | B31: 80 | C31: x | D31: x | E31: x | F31: 混元一气甲 | G31: 50 | H31: 50 | I31: 50 | J31: 80 | K31: 18% | L31: =M31*0.2 | M31: 200
A33: 神羽 | B33: 战斗力 | C33: 祝福值 | D33: 单次材料 | E33: 满值材料 | F33: 名称 | G33: 技空附伤 | H33: 暴击伤害 | I33: 速度值 | J33: 生命值 | K33: 暴击率 | L33: 摄魂战力 | M33: 摄魂数量
A34: 一阶 | B34: 1.5 | C34: 66 | D34: 1 | E34: =ROUNDUP(C34/$N$1+1,0)*D34 | F34: 蜻蜓翅膀 | G34: 2 | H34: x | I34: x | J34: x | K34: x | L34: x | M34: x
A35: 二阶 | B35: 4 | C35: 66 | D35: 2 | E35: =ROUNDUP(C35/$N$1+1,0)*D35 | F35: 彩蝶翅膀 | G35: 4 | H35: 4% | I35: x | J35: x | K35: x | L35: x | M35: x
A36: 三阶 | B36: 8 | C36: 100 | D36: 3 | E36: =ROUNDUP(C36/$N$1+1,0)*D36 | F36: 大鹏展翅 | G36: 8 | H36: 8% | I36: 4 | J36: x | K36: x | L36: x | M36: x
A37: 四阶 | B37: 15 | C37: 200 | D37: 4 | E37: =ROUNDUP(C37/$N$1+1,0)*D37 | F37: 凤凰涅槃 | G37: 12 | H37: 12% | I37: 6 | J37: 8 | K37: x | L37: x | M37: x
A38: 五阶 | B38: 24 | C38: 333 | D38: 6 | E38: =ROUNDUP(C38/$N$1+1,0)*D38 | F38: 巨龙翱翔 | G38: 16 | H38: 16% | I38: 8 | J38: 15 | K38: 7% | L38: =M38*0.2 | M38: 10
A39: 六阶 | B39: 32 | C39: 666 | D39: 8 | E39: =ROUNDUP(C39/$N$1+1,0)*D39 | F39: 精灵之翼 | G39: 22 | H39: 22% | I39: 10 | J39: 24 | K39: 9% | L39: =M39*0.2 | M39: 20
A40: 七阶 | B40: 40 | C40: 1000 | D40: 10 | E40: =ROUNDUP(C40/$N$1+1,0)*D40 | F40: 雷神之翼 | G40: 28 | H40: 28% | I40: 13 | J40: 35 | K40: 11% | L40: =M40*0.2 | M40: 40
A41: 八阶 | B41: 48 | C41: 2000 | D41: 12 | E41: =ROUNDUP(C41/$N$1+1,0)*D41 | F41: 审判之翼 | G41: 34 | H41: 34% | I41: 16 | J41: 48 | K41: 13% | L41: =M41*0.2 | M41: 60
A42: 九阶 | B42: 60 | C42: 2000 | D42: 12 | E42: =ROUNDUP(C42/$N$1+1,0)*D42 | F42: 魔王降临 | G42: 40 | H42: 40% | I42: 20 | J42: 63 | K42: 15% | L42: =M42*0.2 | M42: 80
A43: 十阶 | B43: 80 | C43: x | D43: x | E43: x | F43: 六翼大天使 | G43: 50 | H43: 50% | I43: 25 | J43: 80 | K43: 18% | L43: =M43*0.2 | M43: 200
...

Sheet 奥义奥技
A1: 奥义奥技 | B1: 青龙奥义 | C1: 白虎奥义 | D1: 朱雀奥义 | E1: 玄武奥义 | F1: 祝福详情：奥义等级祝福模式三阶起清，活动期间永久有效。奥义技能祝福模式，永久有效。 | O1: =首页索引!$M$1 | P1: =@IF($O$1="中秋祝福",6,IF($O$1="周年祝福",5,IF($O$1="春节祝福",5,4)))
A2: 奥秘元素 四灵魂石 | B2: 影刃乱舞 | C2: 恐惧洪流 | D2: 移形换影 | E2: 青龙守护 | F2: 常规祝福：奥义等级五阶5星前（含）失败4点祝福值。奥义技能7级前（含）失败3点祝福值。材料120斗豆。 | P2: =@IF($O$1="中秋祝福",4,IF($O$1="周年祝福",4,IF($O$1="春节祝福",4,3)))
B3: 神之泪影 | C3: 弹指神通 | D3: 杨柳甘露 | E3: 玄武守护 | F3: 春节祝福：奥义等级五阶5星前（含）失败5点祝福值。奥义技能7级前（含）失败4点祝福值。材料100斗豆。
B4: 蟠龙翻江 | C4: 瞬杀冲锋 | D4: 吉人天相 | E4: 白虎守护 | F4: 周年祝福：奥义等级五阶5星前（含）失败5点祝福值。奥义技能7级前（含）失败4点祝福值。材料100斗豆。 | Q4: 10000 | R4: 输入伤害
B5: 龙魂风暴 | C5: 狮吼功 | D5: 三花聚顶 | E5: 朱雀守护 | F5: 中秋祝福：奥义等级五阶5星前（含）失败6点祝福值。奥义技能7级前（含）失败4点祝福值。材料200斗豆。 | Q5: 10000 | R5: 输入生命
A6: 奥义等级 | B6: 战斗力 | C6: 祝福值 | D6: 单次材料 | E6: 满值材料 | F6: 生命值 | G6: 技能增伤 | H6: 暴击率 | I6: 抗暴率 | J6: 闪避率 | K6: 命中率 | L6: 效果说明 | P6: 折算公式 | R6: 输出伤害 | S6: 计算1 | T6: 计算2
A7: 一阶0星 | B7: 1 | C7: 12 | D7: 1 | E7: =ROUNDUP(C7/$P$1+1,0)*D7 | F7: 3 | G7: 1% | H7: x | I7: x | J7: x | K7: x | L7: 单次伤害超过生命值上限40%的部分减伤20%。 | P7: 0.80伤害+0.0800血量 | R7: =S7*$Q$4+T7*$Q$5 | S7: 0.8 | T7: 0.08
A8: 一阶1星 | B8: 2 | C8: 16 | D8: 1 | E8: =ROUNDUP(C8/$P$1+1,0)*D8 | F8: 6 | G8: 2% | H8: x | I8: x | J8: x | K8: x | L8: 单次伤害超过生命值上限40%的部分减伤21%。 | P8: 0.79伤害+0.0840血量 | R8: =S8*$Q$4+T8*$Q$5 | S8: 0.79 | T8: 0.084
A9: 一阶2星 | B9: 3.2 | C9: 20 | D9: 2 | E9: =ROUNDUP(C9/$P$1+1,0)*D9 | F9: 9 | G9: 3% | H9: x | I9: x | J9: x | K9: x | L9: 单次伤害超过生命值上限40%的部分减伤22%。 | P9: 0.78伤害+0.0880血量 | R9: =S9*$Q$4+T9*$Q$5 | S9: 0.78 | T9: 0.088
A10: 一阶3星 | B10: 4.6 | C10: 24 | D10: 2 | E10: =ROUNDUP(C10/$P$1+1,0)*D10 | F10: 12 | G10: 4% | H10: x | I10: x | J10: x | K10: x | L10: 单次伤害超过生命值上限40%的部分减伤23%。 | P10: 0.77伤害+0.0920血量 | R10: =S10*$Q$4+T10*$Q$5 | S10: 0.77 | T10: 0.092
A11: 一阶4星 | B11: 6.2 | C11: 30 | D11: 3 | E11: =ROUNDUP(C11/$P$1+1,0)*D11 | F11: 15 | G11: 5% | H11: x | I11: x | J11: x | K11: x | L11: 单次伤害超过生命值上限40%的部分减伤24%。 | P11: 0.76伤害+0.0960血量 | R11: =S11*$Q$4+T11*$Q$5 | S11: 0.76 | T11: 0.096
A12: 一阶5星 | B12: 8 | C12: 36 | D12: 3 | E12: =ROUNDUP(C12/$P$1+1,0)*D12 | F12: 18 | G12: 6% | H12: x | I12: x | J12: x | K12: x | L12: 单次伤害超过生命值上限40%的部分减伤25%。 | P12: 0.75伤害+0.1000血量 | R12: =S12*$Q$4+T12*$Q$5 | S12: 0.75 | T12: 0.1
A13: 二阶0星 | B13: 11 | C13: 44 | D13: 4 | E13: =ROUNDUP(C13/$P$1+1,0)*D13 | F13: 30 | G13: 8% | H13: 2.6% | I13: x | J13: x | K13: x | L13: 单次伤害超过生命值上限38%的部分减伤26%。 | P13: 0.74伤害+0.0988血量 | R13: =S13*$Q$4+T13*$Q$5 | S13: 0.74 | T13: 0.0988
A14: 二阶1星 | B14: 13.5 | C14: 50 | D14: 4 | E14: =ROUNDUP(C14/$P$1+1,0)*D14 | F14: 39 | G14: 10% | H14: 3.3% | I14: x | J14: x | K14: x | L14: 单次伤害超过生命值上限38%的部分减伤27%。 | P14: 0.73伤害+0.1026血量 | R14: =S14*$Q$4+T14*$Q$5 | S14: 0.73 | T14: 0.1026
A15: 二阶2星 | B15: 16.5 | C15: 54 | D15: 5 | E15: =ROUNDUP(C15/$P$1+1,0)*D15 | F15: 48 | G15: 12% | H15: 4% | I15: x | J15: x | K15: x | L15: 单次伤害超过生命值上限38%的部分减伤28%。 | P15: 0.72伤害+0.1064血量 | R15: =S15*$Q$4+T15*$Q$5 | S15: 0.72 | T15: 0.1064
A16: 二阶3星 | B16: 20 | C16: 60 | D16: 5 | E16: =ROUNDUP(C16/$P$1+1,0)*D16 | F16: 57 | G16: 14% | H16: 4.6% | I16: x | J16: x | K16: x | L16: 单次伤害超过生命值上限38%的部分减伤29%。 | P16: 0.71伤害+0.1102血量 | R16: =S16*$Q$4+T16*$Q$5 | S16: 0.71 | T16: 0.1102
A17: 二阶4星 | B17: 24 | C17: 80 | D17: 6 | E17: =ROUNDUP(C17/$P$1+1,0)*D17 | F17: 66 | G17: 16% | H17: 5.3% | I17: x | J17: x | K17: x | L17: 单次伤害超过生命值上限38%的部分减伤30%。 | P17: 0.70伤害+0.1140血量 | R17: =S17*$Q$4+T17*$Q$5 | S17: 0.7 | T17: 0.114
A18: 二阶5星 | B18: 28.5 | C18: 90 | D18: 6 | E18: =ROUNDUP(C18/$P$1+1,0)*D18 | F18: 75 | G18: 18% | H18: 6% | I18: x | J18: x | K18: x | L18: 单次伤害超过生命值上限38%的部分减伤32%。 | P18: 0.68伤害+0.1216血量 | R18: =S18*$Q$4+T18*$Q$5 | S18: 0.68 | T18: 0.1216
... A35: 五阶4星 | B35: 180 | C35: 1800 | D35: 15 | E35: =ROUNDUP(C35/$P$1+1,0)*D35 | F35: 467 | G35: 95% | H35: 28.3% | I35: 28.3% | J35: 28.3% | K35: 28.3% | L35: 单次伤害超过生命值上限26%的部分减伤76%。 | P35: 0.24伤害+0.1976血量 | R35: =S35*$Q$4+T35*$Q$5 | S35: 0.24 | T35: 0.1976
A36: 五阶5星 | B36: 200 | C36: x | D36: x | E36: x | F36: 500 | G36: 100% | H36: 30% | I36: 30% | J36: 30% | K36: 30% | L36: 单次伤害超过生命值上限25%的部分减伤80%。 | P36: 0.20伤害+0.2000血量 | R36: =S36*$Q$4+T36*$Q$5 | S36: 0.2 | T36: 0.2
A38: 技能等级 | B38: 战斗力 | C38: 祝福值 | D38: 单次材料 | E38: 满值材料 | F38: 满值积分 | G38: 生命值 | H38: 技能附伤 | I38: 初始怒气 | J38: 技能命中 | K38: 初始怒气 | L38: 技能附减 | M38: 初始怒气 | N38: 技能暴击 | O38: 初始怒气
A39: 0级 | B39: 0.5 | C39: 18 | D39: 1 | E39: =ROUNDUP(C39/$P$2+1,0)*D39 | F39: =E39*40 | G39: 1 | H39: 1 | I39: 0 | J39: 1% | K39: 0 | L39: 1 | M39: 0 | N39: 1% | O39: 0
A40: 1级 | B40: 1 | C40: 36 | D40: 2 | E40: =ROUNDUP(C40/$P$2+1,0)*D40 | F40: =E40*40 | G40: 5 | H40: 3 | I40: 1 | J40: 2% | K40: 1 | L40: 3 | M40: 1 | N40: 2% | O40: 3
A41: 2级 | B41: 2.5 | C41: 70 | D41: 4 | E41: =ROUNDUP(C41/$P$2+1,0)*D41 | F41: =E41*40 | G41: 21 | H41: 8 | I41: 2 | J41: 4% | K41: 2 | L41: 8 | M41: 4 | N41: 4% | O41: 7
A42: 3级 | B42: 5 | C42: 90 | D42: 6 | E42: =ROUNDUP(C42/$P$2+1,0)*D42 | F42: =E42*40 | G42: 21 | H42: 15 | I42: 3 | J42: 7% | K42: 3 | L42: 15 | M42: 7 | N42: 7% | O42: 11
A43: 4级 | B43: 8.5 | C43: 120 | D43: 8 | E43: =ROUNDUP(C43/$P$2+1,0)*D43 | F43: =E43*40 | G43: 33 | H43: 23 | I43: 4 | J43: 11% | K43: 5 | L43: 23 | M43: 10 | N43: 11% | O43: 15
A44: 5级 | B44: 13 | C44: 160 | D44: 10 | E44: =ROUNDUP(C44/$P$2+1,0)*D44 | F44: =E44*40 | G44: 47 | H44: 32 | I44: 5 | J44: 16% | K44: 7 | L44: 32 | M44: 13 | N44: 16% | O44: 19
A45: 6级 | B45: 18.5 | C45: 200 | D45: 12 | E45: =ROUNDUP(C45/$P$2+1,0)*D45 | F45: =E45*40 | G45: 63 | H45: 42 | I45: 6 | J45: 21% | K45: 9 | L45: 42 | M45: 16 | N45: 21% | O45: 24
A46: 7级 | B46: 25 | C46: 280 | D46: 14 | E46: =ROUNDUP(C46/$P$2+1,0)*D46 | F46: =E46*40 | G46: 82 | H46: 53 | I46: 7 | J46: 27% | K46: 11 | L46: 53 | M46: 20 | N46: 27% | O46: 29
A47: 8级 | B47: 32.5 | C47: 360 | D47: 17 | E47: =ROUNDUP(C47/2+1,0)*D47 | F47: =E47*40 | G47: 107 | H47: 65 | I47: 8 | J47: 33% | K47: 13 | L47: 65 | M47: 24 | N47: 33% | O47: 35
A48: 9级 | B48: 40.5 | C48: 600 | D48: 20 | E48: =ROUNDUP(C48/2+1,0)*D48 | F48: =E48*40 | G48: 143 | H48: 80 | I48: 9 | J48: 40% | K48: 16 | L48: 80 | M48: 29 | N48: 40% | O48: 42
A49: 10级 | B49: 50 | C49: x | D49: x | E49: x | F49: x | G49: 200 | H49: 100 | I49: 10 | J49: 50% | K49: 20 | L49: 100 | M49: 35 | N49: 50% | O49: 50
A50: 适用范围 | B50: 通用值 | H50: 二阶5星 激活青龙 | J50: 三阶5星 激活白虎 | L50: 四阶5星 激活朱雀 | N50: 五阶5星 激活玄武
A52: 技能名称 | B52: 效果说明
A53: 青龙奥义 佛山无影脚 影刃乱舞 | B53: 等级 0 ：造成 50 点+自身力量* 50 %的伤害，自身命中率+31%持续2回合，无视大海。
B54: 等级 1 ：造成 56 点+自身力量* 50 %的伤害，自身命中率+32%持续2回合，无视大海。
B55: 等级 2 ：造成 64 点+自身力量* 60 %的伤害，自身命中率+34%持续2回合，无视大海。
B56: 等级 3 ：造成 73 点+自身力量* 60 %的伤害，自身命中率+37%持续2回合，无视大海。
B57: 等级 4 ：造成 84 点+自身力量* 70 %的伤害，自身命中率+41%持续2回合，无视大海。
B58: 等级 5 ：造成 97 点+自身力量* 70 %的伤害，自身命中率+46%持续3回合，无视大海。
...

Sheet 武器专精
A1: 武器专精 | B1: 名称 | D1: 祝福详情：专精等级祝福模式三阶起清，活动期间永久有效。专精武器祝福模式3级起清，活动期间永久有效。 | M1: =首页索引!$M$1 | N1: =@IF(M1="中秋祝福",9,IF(M1="周年祝福",8,IF(M1="春节祝福",7,6)))
A2: 武器符文石 千年寒铁 | B2: 专精等级 | C2: 专精控制 | D2: 常规祝福：专精等级四阶5星前（含）失败6点祝福值，其余失败5点祝福值。专精武器失败4点祝福值。材料120斗豆/斗币。 | N2: =@IF(M1="中秋祝福",7,IF(M1="周年祝福",5,IF(M1="春节祝福",5,5)))
D3: 春节祝福：专精等级四阶5星前（含）失败7点祝福值，其余失败5点祝福值。专精武器失败5点祝福值。材料100斗豆/斗币。 | N3: =@IF(M1="中秋祝福",6,IF(M1="周年祝福",5,IF(M1="春节祝福",5,4)))
B4: 专精吸血 | C4: 专精凝神 | D4: 周年祝福：专精等级四阶5星前（含）失败8点祝福值，其余失败5点祝福值。专精武器失败5点祝福值。材料100斗豆/斗币。
D5: 中秋祝福：专精等级四阶5星前（含）失败9点祝福值，其余失败7点祝福值。专精武器失败6点祝福值。材料200斗豆/斗币。
A6: 专精等级 | B6: 战斗力 | C6: 祝福值 | D6: 单次材料 | E6: 满值材料 | F6: 满值积分 | G6: 武器附伤 | H6: 武器附减 | I6: 武器暴击 | J6: 武器抗暴 | K6: 生命值 | L6: 闪避率 | M6: 命中率
A7: 一阶0星 | B7: 0.5 | C7: 15 | D7: 1 | E7: =ROUNDUP(C7/$N$1+1,0)*D7 | F7: =E7*40 | G7: 1 | H7: 1 | I7: x | J7: x | K7: x | L7: x | M7: x
A8: 一阶1星 | B8: 1 | C8: 15 | D8: 1 | E8: =ROUNDUP(C8/$N$1+1,0)*D8 | F8: =E8*40 | G8: 2 | H8: 2 | I8: x | J8: x | K8: x | L8: x | M8: x
A9: 一阶2星 | B9: 1.5 | C9: 15 | D9: 2 | E9: =ROUNDUP(C9/$N$1+1,0)*D9 | F9: =E9*40 | G9: 3 | H9: 3 | I9: x | J9: x | K9: x | L9: x | M9: x
A10: 一阶3星 | B10: 2 | C10: 15 | D10: 2 | E10: =ROUNDUP(C10/$N$1+1,0)*D10 | F10: =E10*40 | G10: 4 | H10: 4 | I10: x | J10: x | K10: x | L10: x | M10: x
A11: 一阶4星 | B11: 2.5 | C11: 15 | D11: 3 | E11: =ROUNDUP(C11/$N$1+1,0)*D11 | F11: =E11*40 | G11: 5 | H11: 5 | I11: x | J11: x | K11: x | L11: x | M11: x
A12: 一阶5星 | B12: 3 | C12: 15 | D12: 3 | E12: =ROUNDUP(C12/$N$1+1,0)*D12 | F12: =E12*40 | G12: 6 | H12: 6 | I12: x | J12: x | K12: x | L12: x | M12: x
A13: 二阶0星 | B13: 5 | C13: 20 | D13: 4 | E13: =ROUNDUP(C13/$N$1+1,0)*D13 | F13: =E13*40 | G13: 8 | H13: 8 | I13: 2.6% | J13: 2.6% | K13: x | L13: x | M13: x
A14: 二阶1星 | B14: 6.3 | C14: 24 | D14: 4 | E14: =ROUNDUP(C14/$N$1+1,0)*D14 | F14: =E14*40 | G14: 10 | H14: 10 | I14: 3.3% | J14: 3.3% | K14: x | L14: x | M14: x
A15: 二阶2星 | B15: 7.6 | C15: 24 | D15: 5 | E15: =ROUNDUP(C15/$N$1+1,0)*D15 | F15: =E15*40 | G15: 12 | H15: 12 | I15: 4% | J15: 4% | K15: x | L15: x | M15: x
A16: 二阶3星 | B16: 9 | C16: 30 | D16: 5 | E16: =ROUNDUP(C16/$N$1+1,0)*D16 | F16: =E16*40 | G16: 14 | H16: 14 | I16: 4.6% | J16: 4.6% | K16: x | L16: x | M16: x
A17: 二阶4星 | B17: 10.5 | C17: 30 | D17: 6 | E17: =ROUNDUP(C17/$N$1+1,0)*D17 | F17: =E17*40 | G17: 16 | H17: 16 | I17: 5.3% | J17: 5.3% | K17: x | L17: x | M17: x
A18: 二阶5星 | B18: 12 | C18: 40 | D18: 6 | E18: =ROUNDUP(C18/$N$1+1,0)*D18 | F18: =E18*40 | G18: 18 | H18: 18 | I18: 6% | J18: 6% | K18: x | L18: x | M18: x
... A30: 四阶5星 | B30: 49 | C30: 600 | D30: 12 | E30: =ROUNDUP(C30/$N$1+1,0)*D30 | F30: =E30*40 | G30: 51 | H30: 51 | I30: 20% | J30: 20% | K30: 72 | L30: 20% | M30: x
A31: 五阶0星 | B31: 56 | C31: 750 | D31: 13 | E31: =ROUNDUP(C31/$N$2+1,0)*D31 | F31: =E31*40 | G31: 54 | H31: 54 | I31: 21.6% | J31: 21.6% | K31: 80 | L31: 21.6% | M31: 21.6%
A32: 五阶1星 | B32: 60 | C32: 1000 | D32: 13 | E32: =ROUNDUP(C32/$N$2+1,0)*D32 | F32: =E32*40 | G32: 58 | H32: 58 | I32: 23.3% | J32: 23.3% | K32: 92 | L32: 23.3% | M32: 23.3%
A33: 五阶2星 | B33: 65 | C33: 1200 | D33: 14 | E33: =ROUNDUP(C33/$N$2+1,0)*D33 | F33: =E33*40 | G33: 64 | H33: 64 | I33: 25% | J33: 25% | K33: 110 | L33: 25% | M33: 25%
A34: 五阶3星 | B34: 70 | C34: 1500 | D34: 14 | E34: =ROUNDUP(C34/$N$2+1,0)*D34 | F34: =E34*40 | G34: 72 | H34: 72 | I34: 26.6% | J34: 26.6% | K34: 135 | L34: 26.6% | M34: 26.6%
A35: 五阶4星 | B35: 75 | C35: 2000 | D35: 15 | E35: =ROUNDUP(C35/$N$2+1,0)*D35 | F35: =E35*40 | G35: 84 | H35: 84 | I35: 28.3% | J35: 28.3% | K35: 170 | L35: 28.3% | M35: 28.3%
A36: 五阶5星 | B36: 80 | C36: x | D36: x | E36: x | F36: x | G36: 100 | H36: 100 | I36: 30% | J36: 30% | K36: 220 | L36: 30% | M36: 30%
A38: 武器栏1 | B38: 属性 | C38: 0级 | D38: 1级 | E38: 2级 | F38: 3级 | G38: 4级 | H38: 5级 | I38: 6级 | J38: 7级 | K38: 8级 | L38: 9级 | M38: 10级
A39: 专精控制 激活条件 专精等级 二阶 0 星 | B39: 祝福值 | C39: 10 | D39: 10 | E39: 20 | F39: 30 | G39: 50 | H39: 75 | I39: 120 | J39: 200 | K39: 300 | L39: 600 | M39: 降低对方50%伤害持续3回合
B40: 单次材料 | C40: 1 | D40: 2 | E40: 3 | F40: 4 | G40: 5 | H40: 6 | I40: 7 | J40: 8 | K40: 9 | L40: 10
B41: 满值材料 | C41: =ROUNDUP((C39/$N$3+1),0)*C40 | D41: =ROUNDUP((D39/$N$3+1),0)*D40 | E41: =ROUNDUP((E39/$N$3+1),0)*E40 | F41: =ROUNDUP((F39/$N$3+1),0)*F40 | G41: =ROUNDUP((G39/$N$3+1),0)*G40 | H41: =ROUNDUP((H39/$N$3+1),0)*H40 | I41: =ROUNDUP((I39/$N$3+1),0)*I40 | J41: =ROUNDUP((J39/$N$3+1),0)*J40 | ... L41: =ROUNDUP((L39/$N$3+1),0)*L40
B42: 满值积分 | C42: =C41*40 | D42: =D41*40 | E42: =E41*40 | F42: =F41*40 | G42: =G41*40 | H42: =H41*40 | I42: =I41*40 | J42: =J41*40 | ... L42: =L41*40
B43: 战斗力 | C43: 1 | D43: 1.4 | E43: 1.8 | F43: 2.4 | G43: 3 | H43: 3.8 | I43: 4.6 | J43: 5.6 | K43: 6.6 | L43: 8 | M43: 10
B44: 该武增伤 | C44: 5% | D44: 7% | E44: 9% | F44: 12% | G44: 15% | H44: 19% | I44: 23% | J44: 28% | K44: 33% | L44: 40% | M44: 50%
B45: 该武连击 | C45: 5% | D45: 7% | E45: 9% | F45: 12% | G45: 15% | H45: 19% | I45: 23% | J45: 28% | K45: 33% | L45: 40% | M45: 50%
B46: 该武忽略 | C46: 10% | D46: 14% | E46: 18% | F46: 24% | G46: 30% | H46: 38% | I46: 46% | J46: 56% | K46: 66% | L46: 80% | M46: 100%
A48: 武器栏2 | B48: 属性 | C48: 0级 | D48: 1级 | E48: 2级 | F48: 3级 | G48: 4级 | H48: 5级 | I48: 6级 | J48: 7级 | K48: 8级 | L48: 9级 | M48: 10级
A49: 专精吸血 激活条件 专精等级 四阶 3 星 | B49: 祝福值 | C49: 10 | D49: 10 | E49: 24 | F49: 50 | G49: 66 | H49: 100 | I49: 150 | J49: 240 | K49: 400 | L49: 750 | M49: 忽略反击 忽略反弹
B50: 单次材料 | C50: 1 | D50: 2 | E50: 3 | F50: 4 | G50: 5 | H50: 6 | I50: 7 | J50: 8 | K50: 9 | L50: 10
B51: 满值材料 | C51: =ROUNDUP((C49/$N$3+1),0)*C50 | D51: =ROUNDUP((D49/$N$3+1),0)*D50 | E51: =ROUNDUP((E49/$N$3+1),0)*E50 | F51: =ROUNDUP((F49/$N$3+1),0)*F50 | G51: =ROUNDUP((G49/$N$3+1),0)*G50 | H51: =ROUNDUP((H49/$N$3+1),0)*H50 | I51: =ROUNDUP((I49/$N$3+1),0)*I50 | J51: =ROUNDUP((J49/$N$3+1),0)*J50 | ... L51: =ROUNDUP((L49/$N$3+1),0)*L50
B52: 满值积分 | C52: =C51*40 | D52: =D51*40 | E52: =E51*40 | F52: =F51*40 | G52: =G51*40 | H52: =H51*40 | I52: =I51*40 | J52: =J51*40 | ... L52: =L51*40
B53: 战斗力 | C53: 1.2 | D53: 1.7 | E53: 2.2 | F53: 2.9 | G53: 3.6 | H53: 4.5 | I53: 5.5 | J53: 6.7 | K53: 7.9 | L53: 9.6 | M53: 12
...

Sheet 武器封印
A1: 武器封印 | B1: 名称 | E1: 祝福详情：封印等级祝福模式三阶起清，暂无活动。封印武器祝福模式3级起清，暂无活动。 | M1: =首页索引!$M$1 | N1: =@IF(M1="中秋祝福",2,IF(M1="周年祝福",2,IF(M1="春节祝福",2,2)))
A2: 武器符咒 石中剑 | B2: 封印等级 | C2: 大型封印 | D2: 中型封印 | E2: 常规祝福：封印等级失败2点祝福值。封印武器失败2点祝福值。材料200斗豆。 | N2: =@IF(M1="中秋祝福",2,IF(M1="周年祝福",2,IF(M1="春节祝福",2,2)))
E3: 春节祝福：封印等级失败2点祝福值。封印武器失败2点祝福值。材料200斗豆。
B4: 封印加成 | C4: 小型封印 | D4: 投掷封印 | E4: 周年祝福：封印等级失败2点祝福值。封印武器失败2点祝福值。材料200斗豆。
E5: 中秋祝福：封印等级失败2点祝福值。封印武器失败2点祝福值。材料200斗豆。
A6: 封印等级 | B6: 战斗力 | C6: 祝福值 | D6: 单次材料 | E6: 满值材料 | F6: 满值斗豆 | G6: 武器附伤 | H6: 武器附减 | I6: 武器暴击 | J6: 武器抗暴 | K6: 生命值 | L6: 闪避率 | M6: 命中率
A7: 一阶0星 | B7: 0.5 | C7: 15 | D7: 1 | E7: =ROUNDUP(C7/$N$1+1,0)*D7 | F7: =E7*200 | G7: 1 | H7: 1 | I7: x | J7: x | K7: x | L7: x | M7: x
A8: 一阶1星 | B8: 1 | C8: 15 | D8: 1 | E8: =ROUNDUP(C8/$N$1+1,0)*D8 | F8: =E8*200 | G8: 2 | H8: 2 | I8: x | J8: x | K8: x | L8: x | M8: x
A9: 一阶2星 | B9: 1.5 | C9: 15 | D9: 2 | E9: =ROUNDUP(C9/$N$1+1,0)*D9 | F9: =E9*200 | G9: 3 | H9: 3 | I9: x | J9: x | K9: x | L9: x | M9: x
A10: 一阶3星 | B10: 2 | C10: 15 | D10: 2 | E10: =ROUNDUP(C10/$N$1+1,0)*D10 | F10: =E10*200 | G10: 4 | H10: 4 | I10: x | J10: x | K10: x | L10: x | M10: x
A11: 一阶4星 | B11: 2.5 | C11: 15 | D11: 3 | E11: =ROUNDUP(C11/$N$1+1,0)*D11 | F11: =E11*200 | G11: 5 | H11: 5 | I11: x | J11: x | K11: x | L11: x | M11: x
A12: 一阶5星 | B12: 3 | C12: 15 | D12: 3 | E12: =ROUNDUP(C12/$N$1+1,0)*D12 | F12: =E12*200 | G12: 6 | H12: 6 | I12: x | J12: x | K12: x | L12: x | M12: x
A13: 二阶0星 | B13: 5 | C13: 20 | D13: 4 | E13: =ROUNDUP(C13/$N$1+1,0)*D13 | F13: =E13*200 | G13: 8 | H13: 8 | I13: 2.6% | J13: 2.6% | K13: x | L13: x | M13: x
A14: 二阶1星 | B14: 6.3 | C14: 24 | D14: 4 | E14: =ROUNDUP(C14/$N$1+1,0)*D14 | F14: =E14*200 | G14: 10 | H14: 10 | I14: 3.3% | J14: 3.3% | K14: x | L14: x | M14: x
A15: 二阶2星 | B15: 7.6 | C15: 24 | D15: 5 | E15: =ROUNDUP(C15/$N$1+1,0)*D15 | F15: =E15*200 | G15: 12 | H15: 12 | I15: 4% | J15: 4% | K15: x | L15: x | M15: x
A16: 二阶3星 | B16: 9 | C16: 30 | D16: 5 | E16: =ROUNDUP(C16/$N$1+1,0)*D16 | F16: =E16*200 | G16: 14 | H16: 14 | I16: 4.6% | J16: 4.6% | K16: x | L16: x | M16: x
A17: 二阶4星 | B17: 10.5 | C17: 30 | D17: 6 | E17: =ROUNDUP(C17/$N$1+1,0)*D17 | F17: =E17*200 | G17: 16 | H17: 16 | I17: 5.3% | J17: 5.3% | K17: x | L17: x | M17: x
A18: 二阶5星 | B18: 12 | C18: 40 | D18: 6 | E18: =ROUNDUP(C18/$N$1+1,0)*D18 | F18: =E18*200 | G18: 18 | H18: 18 | I18: 6% | J18: 6% | K18: x | L18: x | M18: x
... A35: 五阶4星 | B35: 75 | C35: 2000 | D35: 15 | E35: =ROUNDUP(C35/$N$1+1,0)*D35 | F35: =E35*200 | G35: 84 | H35: 84 | I35: 28.3% | J35: 28.3% | K35: 170 | L35: 28.3% | M35: 28.3%
A36: 五阶5星 | B36: 80 | C36: x | D36: x | E36: x | F36: x | G36: 100 | H36: 100 | I36: 30% | J36: 30% | K36: 220 | L36: 30% | M36: 30%
A38: 祭坛等级 | B38: 属性 | C38: 0级 | D38: 1级 | E38: 2级 | F38: 3级 | G38: 4级 | H38: 5级 | I38: 6级 | J38: 7级 | K38: 8级 | L38: 9级 | M38: 10级
A39: 大型封印 激活条件 封印等级 二阶 0 星 | B39: 战斗力 | C39: 1.5 | D39: 2.1 | E39: 2.7 | F39: 3.6 | G39: 4.5 | H39: 5.7 | I39: 6.9 | J39: 8.4 | K39: 9.9 | L39: 12.0 | M39: 15.0
B40: 封印率 | C40: 10% | D40: 15% | E40: 20% | F40: 25% | G40: 30% | H40: 35% | I40: 40% | J40: 45% | K40: 50% | L40: 60% | M40: 80%
B41: 祝福值 | C41: 10 | D41: 10 | E41: 24 | F41: 50 | G41: 75 | H41: 120 | I41: 200 | J41: 300 | K41: 500 | L41: 800 | M41: x
